Workbook

Sheet README
A1: Bajaj Finance Ltd — Credit-risk dataset, FY2016-17 to FY2025-26 (10 years)
A3: Basis | B3: Consolidated (BFL + Bajaj Housing Finance + Bajaj Financial Securities), ₹ crore, years ending 31 March — unless a column says 'standalone'.
A4: Colour code | B4: Blue = figure from company disclosures · Black = formula · Green = linked from another sheet · Yellow = not yet collected · Grey = not applicable (pre-Ind AS).
A5: Loss basis | B5: Loan losses, credit cost and PAT are on the ORIGINAL presentation basis (before the FY26 reclassification of recoveries on written-off loans), so all years compare. Restated FY25/FY26 figures are noted in Credit_Losses.
A6: NPA note | B6: NPA recognition tightened over time: 4 months overdue in FY17, 3 months from FY18, strict 91 dpd from Dec-2021 — ratios are not strictly comparable across these breaks.
A7: Accounting break | B7: FY2016-17 is under previous Indian GAAP (no Stage 1/2/3 or ECL — grey cells). Ind AS applies from FY2017-18 (as restated in the FY19 report). FY17 AUM and ratios are on the company's standalone IGAAP basis.
A9: Sheet | B9: What it holds
A10: Formulas_Guide | B10: Every formula used: plain-English version, purpose, and the actual Excel formula.
A11: Master_Dataset | B11: One row per year with every key variable, linked from the topic sheets — use this for graphs, correlation and your risk index.
A12: AUM | B12: Total AUM (consolidated & standalone), AUF, growth.
A13: Segment_AUM | B13: Product-wise AUM and segment GNPA, with secured/unsecured and risk tier; broad 5-bucket mix.
A14: Asset_Quality | B14: GNPA %, NNPA %, Gross NPA ₹, Net NPA ₹, PCR.
A15: Stage_ECL | B15: Stage 1/2/3 gross loans and ECL allowance by stage, coverage ratios.
... A21: Sources | B21: Every document used, with links and page/slide numbers; list of remaining gaps.

Sheet Master_Dataset
A1: Master dataset — Bajaj Finance (consolidated), one row per year
A2: All cells link to the topic sheets (green) — edit numbers there, not here. Use this sheet for charts, correlations and the credit-risk index.
A4: Financial year | B4: Company | C4: AUM (₹ cr) | D4: AUM growth % | E4: GNPA % | F4: NNPA % | G4: Gross NPA ₹ | H4: Net NPA ₹ | I4: PCR % | J4: Stage 2 % of loans | K4: Stage 3 % of loans | L4: Loan losses (₹ cr) | M4: Credit cost % (reported) | N4: Credit cost % (calc, avg AUM) | O4: Write-offs (₹ cr) | P4: CRAR % | Q4: Tier 1 % | R4: Leverage (x) | S4: Debt / Equity (x) | T4: NTI (₹ cr) | U4: PAT (₹ cr) | V4: ROA % | W4: ROE % | X4: Opex / NTI | Y4: Loan losses / NTI | Z4: Liquidity buffer (₹ cr) | AA4: LCR | AB4: Deposits % of borrowings | AC4: ALM gap ≤1 month | AD4: ALM gap ≤1 year | AE4: Cost of funds
A5: FY2016-17 | B5: Bajaj Finance | C5: =IF(AUM!B5="","",AUM!B5) -> 60196 | D5: =IF(AUM!E5="","",AUM!E5) | E5: =IF(Asset_Quality!B5="","",Asset_Quality!B5) -> 0.0168 | F5: =IF(Asset_Quality!C5="","",Asset_Quality!C5) -> 0.0044 | G5: =IF(Asset_Quality!D5="","",Asset_Quality!D5) | H5: =IF(Asset_Quality!E5="","",Asset_Quality!E5) | I5: =IF(Asset_Quality!F5="","",Asset_Quality!F5) -> 0.74 | J5: =IF(Stage_ECL!J5="","",Stage_ECL!J5) | K5: =IF(Stage_ECL!K5="","",Stage_ECL!K5) | L5: =IF(Credit_Losses!B5="","",Credit_Losses!B5) -> 804 | M5: =IF(Credit_Losses!C5="","",Credit_Losses!C5) -> 0.0161 | N5: =IF(Credit_Losses!G5="","",Credit_Losses!G5) | O5: =IF(Credit_Losses!D5="","",Credit_Losses!D5) | P5: =IF(Capital!B5="","",Capital!B5) -> 0.203 | Q5: =IF(Capital!C5="","",Capital!C5) -> 0.146 | R5: =IF(Capital!E5="","",Capital!E5) -> 6.6 | S5: =IF(Capital!I5="","",Capital!I5) | T5: =IF(Profitability!D5="","",Profitability!D5) -> 6186 | U5: =IF(Profitability!I5="","",Profitability!I5) -> 1837 | V5: =IF(Profitability!J5="","",Profitability!J5) -> 0.037 | W5: =IF(Profitability!K5="","",Profitability!K5) -> 0.216 | X5: =IF(Profitability!M5="","",Profitability!M5) -> 0.41448432 | Y5: =IF(Profitability!N5="","",Profitability!N5) -> 0.1299709 | Z5: =IF(Liquidity!B5="","",Liquidity!B5) | AA5: =IF(Liquidity!C5="","",Liquidity!C5) | AB5: =IF(Liquidity!F5="","",Liquidity!F5) -> 0.08 | AC5: =IF(Liquidity!L5="","",Liquidity!L5) -> 1.19 | AD5: =IF(Liquidity!M5="","",Liquidity!M5) -> 0.5 | AE5: =IF(Profitability!L5="","",Profitability!L5) -> 0.09
A6: FY2017-18 | B6: Bajaj Finance | C6: =IF(AUM!B6="","",AUM!B6) -> 82422 | D6: =IF(AUM!E6="","",AUM!E6) -> 0.36922719 | E6: =IF(Asset_Quality!B6="","",Asset_Quality!B6) -> 0.0141 | F6: =IF(Asset_Quality!C6="","",Asset_Quality!C6) -> 0.0043 | G6: =IF(Asset_Quality!D6="","",Asset_Quality!D6) -> 1200 | H6: =IF(Asset_Quality!E6="","",Asset_Quality!E6) -> 390 | I6: =IF(Asset_Quality!F6="","",Asset_Quality!F6) -> 0.7 | J6: =IF(Stage_ECL!J6="","",Stage_ECL!J6) -> 0.013418824 | K6: =IF(Stage_ECL!K6="","",Stage_ECL!K6) -> 0.014882244 | L6: =IF(Credit_Losses!B6="","",Credit_Losses!B6) -> 1030 | M6: =IF(Credit_Losses!C6="","",Credit_Losses!C6) -> 0.015 | N6: =IF(Credit_Losses!G6="","",Credit_Losses!G6) -> 0.01444418 | O6: =IF(Credit_Losses!D6="","",Credit_Losses!D6) | P6: =IF(Capital!B6="","",Capital!B6) -> 0.2471 | Q6: =IF(Capital!C6="","",Capital!C6) -> 0.1968 | R6: =IF(Capital!E6="","",Capital!E6) -> 5.4 | S6: =IF(Capital!I6="","",Capital!I6) | T6: =IF(Profitability!D6="","",Profitability!D6) -> 8143 | U6: =IF(Profitability!I6="","",Profitability!I6) -> 2496 | V6: =IF(Profitability!J6="","",Profitability!J6) -> 0.037 | W6: =IF(Profitability!K6="","",Profitability!K6) -> 0.201 | X6: =IF(Profitability!M6="","",Profitability!M6) -> 0.4015719 | Y6: =IF(Profitability!N6="","",Profitability!N6) -> 0.12648901 | Z6: =IF(Liquidity!B6="","",Liquidity!B6) | AA6: =IF(Liquidity!C6="","",Liquidity!C6) | AB6: =IF(Liquidity!F6="","",Liquidity!F6) -> 0.12 | AC6: =IF(Liquidity!L6="","",Liquidity!L6) -> 1.2 | AD6: =IF(Liquidity!M6="","",Liquidity!M6) -> 0.96 | AE6: =IF(Profitability!L6="","",Profitability!L6) -> 0.0824
A7: FY2018-19 | B7: Bajaj Finance | C7: =IF(AUM!B7="","",AUM!B7) -> 115888 | D7: =IF(AUM!E7="","",AUM!E7) -> 0.40603237 | E7: =IF(Asset_Quality!B7="","",Asset_Quality!B7) -> 0.0154 | F7: =IF(Asset_Quality!C7="","",Asset_Quality!C7) -> 0.0063 | G7: =IF(Asset_Quality!D7="","",Asset_Quality!D7) -> 1812 | H7: =IF(Asset_Quality!E7="","",Asset_Quality!E7) -> 735 | I7: =IF(Asset_Quality!F7="","",Asset_Quality!F7) -> 0.6 | J7: =IF(Stage_ECL!J7="","",Stage_ECL!J7) -> 0.017552435 | K7: =IF(Stage_ECL!K7="","",Stage_ECL!K7) -> 0.015815521 | L7: =IF(Credit_Losses!B7="","",Credit_Losses!B7) -> 1501 | M7: =IF(Credit_Losses!C7="","",Credit_Losses!C7) -> 0.0155 | N7: =IF(Credit_Losses!G7="","",Credit_Losses!G7) -> 0.015137915 | O7: =IF(Credit_Losses!D7="","",Credit_Losses!D7) -> 965 | P7: =IF(Capital!B7="","",Capital!B7) -> 0.2066 | Q7: =IF(Capital!C7="","",Capital!C7) -> 0.1627 | R7: =IF(Capital!E7="","",Capital!E7) -> 6.3 | S7: =IF(Capital!I7="","",Capital!I7) -> 5.1575367 | T7: =IF(Profitability!D7="","",Profitability!D7) -> 11877 | U7: =IF(Profitability!I7="","",Profitability!I7) -> 3995 | V7: =IF(Profitability!J7="","",Profitability!J7) -> 0.042 | W7: =IF(Profitability!K7="","",Profitability!K7) -> 0.2248 | X7: =IF(Profitability!M7="","",Profitability!M7) -> 0.35337206 | Y7: =IF(Profitability!N7="","",Profitability!N7) -> 0.12637872 | Z7: =IF(Liquidity!B7="","",Liquidity!B7) | AA7: =IF(Liquidity!C7="","",Liquidity!C7) | AB7: =IF(Liquidity!F7="","",Liquidity!F7) -> 0.13 | AC7: =IF(Liquidity!L7="","",Liquidity!L7) -> 0.51 | AD7: =IF(Liquidity!M7="","",Liquidity!M7) -> 0.57 | AE7: =IF(Profitability!L7="","",Profitability!L7) -> 0.0827
A8: FY2019-20 | B8: Bajaj Finance | C8: =IF(AUM!B8="","",AUM!B8) -> 147153 | D8: =IF(AUM!E8="","",AUM!E8) -> 0.26978635 | E8: =IF(Asset_Quality!B8="","",Asset_Quality!B8) -> 0.0161 | F8: =IF(Asset_Quality!C8="","",Asset_Quality!C8) -> 0.0065 | G8: =IF(Asset_Quality!D8="","",Asset_Quality!D8) -> 2363 | H8: =IF(Asset_Quality!E8="","",Asset_Quality!E8) -> 938 | I8: =IF(Asset_Quality!F8="","",Asset_Quality!F8) -> 0.6 | J8: =IF(Stage_ECL!J8="","",Stage_ECL!J8) -> 0.021695382 | K8: =IF(Stage_ECL!K8="","",Stage_ECL!K8) -> 0.01628532 | L8: =IF(Credit_Losses!B8="","",Credit_Losses!B8) -> 3929 | M8: =IF(Credit_Losses!C8="","",Credit_Losses!C8) -> 0.031 | N8: =IF(Credit_Losses!G8="","",Credit_Losses!G8) -> 0.02987367 | O8: =IF(Credit_Losses!D8="","",Credit_Losses!D8) -> 2248 | P8: =IF(Capital!B8="","",Capital!B8) -> 0.2501 | Q8: =IF(Capital!C8="","",Capital!C8) -> 0.2127 | R8: =IF(Capital!E8="","",Capital!E8) -> 5.1 | S8: =IF(Capital!I8="","",Capital!I8) -> 4.0152809 | T8: =IF(Profitability!D8="","",Profitability!D8) -> 16913 | U8: =IF(Profitability!I8="","",Profitability!I8) -> 5264 | V8: =IF(Profitability!J8="","",Profitability!J8) -> 0.0415 | W8: =IF(Profitability!K8="","",Profitability!K8) -> 0.2024 | X8: =IF(Profitability!M8="","",Profitability!M8) -> 0.33477207 | Y8: =IF(Profitability!N8="","",Profitability!N8) -> 0.23230651 | Z8: =IF(Liquidity!B8="","",Liquidity!B8) -> 15725 | AA8: =IF(Liquidity!C8="","",Liquidity!C8) | AB8: =IF(Liquidity!F8="","",Liquidity!F8) -> 0.17 | AC8: =IF(Liquidity!L8="","",Liquidity!L8) -> 2.2 | AD8: =IF(Liquidity!M8="","",Liquidity!M8) -> 0.54 | AE8: =IF(Profitability!L8="","",Profitability!L8) -> 0.0839
A9: FY2020-21 | B9: Bajaj Finance | C9: =IF(AUM!B9="","",AUM!B9) -> 152947 | D9: =IF(AUM!E9="","",AUM!E9) -> 0.039373985 | E9: =IF(Asset_Quality!B9="","",Asset_Quality!B9) -> 0.0179 | F9: =IF(Asset_Quality!C9="","",Asset_Quality!C9) -> 0.0075 | G9: =IF(Asset_Quality!D9="","",Asset_Quality!D9) -> 2731 | H9: =IF(Asset_Quality!E9="","",Asset_Quality!E9) -> 1136 | I9: =IF(Asset_Quality!F9="","",Asset_Quality!F9) -> 0.58 | J9: =IF(Stage_ECL!J9="","",Stage_ECL!J9) -> 0.044537899 | K9: =IF(Stage_ECL!K9="","",Stage_ECL!K9) -> 0.018086692 | L9: =IF(Credit_Losses!B9="","",Credit_Losses!B9) -> 5969 | M9: =IF(Credit_Losses!C9="","",Credit_Losses!C9) -> 0.0414 | N9: =IF(Credit_Losses!G9="","",Credit_Losses!G9) -> 0.039780073 | O9: =IF(Credit_Losses!D9="","",Credit_Losses!D9) -> 5554 | P9: =IF(Capital!B9="","",Capital!B9) -> 0.2831 | Q9: =IF(Capital!C9="","",Capital!C9) -> 0.2511 | R9: =IF(Capital!E9="","",Capital!E9) -> 4.7 | S9: =IF(Capital!I9="","",Capital!I9) | T9: =IF(Profitability!D9="","",Profitability!D9) -> 17269 | U9: =IF(Profitability!I9="","",Profitability!I9) -> 4420 | V9: =IF(Profitability!J9="","",Profitability!J9) -> 0.0307 | W9: =IF(Profitability!K9="","",Profitability!K9) -> 0.1277 | X9: =IF(Profitability!M9="","",Profitability!M9) -> 0.30737159 | Y9: =IF(Profitability!N9="","",Profitability!N9) -> 0.34564827 | Z9: =IF(Liquidity!B9="","",Liquidity!B9) -> 16485 | AA9: =IF(Liquidity!C9="","",Liquidity!C9) -> 2.7 | AB9: =IF(Liquidity!F9="","",Liquidity!F9) -> 0.2 | AC9: =IF(Liquidity!L9="","",Liquidity!L9) -> 2.16 | AD9: =IF(Liquidity!M9="","",Liquidity!M9) -> 0.8 | AE9: =IF(Profitability!L9="","",Profitability!L9) -> 0.0784
A10: FY2021-22 | B10: Bajaj Finance | C10: =IF(AUM!B10="","",AUM!B10) -> 197452 | D10: =IF(AUM!E10="","",AUM!E10) -> 0.29098315 | E10: =IF(Asset_Quality!B10="","",Asset_Quality!B10) -> 0.016 | F10: =IF(Asset_Quality!C10="","",Asset_Quality!C10) -> 0.0068 | G10: =IF(Asset_Quality!D10="","",Asset_Quality!D10) -> 3133 | H10: =IF(Asset_Quality!E10="","",Asset_Quality!E10) -> 1315 | I10: =IF(Asset_Quality!F10="","",Asset_Quality!F10) -> 0.58 | J10: =IF(Stage_ECL!J10="","",Stage_ECL!J10) -> 0.019716282 | K10: =IF(Stage_ECL!K10="","",Stage_ECL!K10) -> 0.015998734 | L10: =IF(Credit_Losses!B10="","",Credit_Losses!B10) -> 4803 | M10: =IF(Credit_Losses!C10="","",Credit_Losses!C10) -> 0.0284 | N10: =IF(Credit_Losses!G10="","",Credit_Losses!G10) -> 0.027414462 | O10: =IF(Credit_Losses!D10="","",Credit_Losses!D10) -> 4807 | P10: =IF(Capital!B10="","",Capital!B10) -> 0.2722 | Q10: =IF(Capital!C10="","",Capital!C10) -> 0.2475 | R10: =IF(Capital!E10="","",Capital!E10) -> 4.9 | S10: =IF(Capital!I10="","",Capital!I10) | T10: =IF(Profitability!D10="","",Profitability!D10) -> 21894 | U10: =IF(Profitability!I10="","",Profitability!I10) -> 7028 | V10: =IF(Profitability!J10="","",Profitability!J10) -> 0.0416 | W10: =IF(Profitability!K10="","",Profitability!K10) -> 0.1743 | X10: =IF(Profitability!M10="","",Profitability!M10) -> 0.3465333 | Y10: =IF(Profitability!N10="","",Profitability!N10) -> 0.21937517 | Z10: =IF(Liquidity!B10="","",Liquidity!B10) -> 10110 | AA10: =IF(Liquidity!C10="","",Liquidity!C10) -> 1.34 | AB10: =IF(Liquidity!F10="","",Liquidity!F10) -> 0.19 | AC10: =IF(Liquidity!L10="","",Liquidity!L10) -> 0.31 | AD10: =IF(Liquidity!M10="","",Liquidity!M10) -> 0.32 | AE10: =IF(Profitability!L10="","",Profitability!L10) -> 0.0681
A11: FY2022-23 | B11: Bajaj Finance | C11: =IF(AUM!B11="","",AUM!B11) -> 247379 | D11: =IF(AUM!E11="","",AUM!E11) -> 0.25285639 | E11: =IF(Asset_Quality!B11="","",Asset_Quality!B11) -> 0.0094 | F11: =IF(Asset_Quality!C11="","",Asset_Quality!C11) -> 0.0034 | G11: =IF(Asset_Quality!D11="","",Asset_Quality!D11) -> 2313 | H11: =IF(Asset_Quality!E11="","",Asset_Quality!E11) -> 837 | I11: =IF(Asset_Quality!F11="","",Asset_Quality!F11) -> 0.64 | J11: =IF(Stage_ECL!J11="","",Stage_ECL!J11) -> 0.012297475 | K11: =IF(Stage_ECL!K11="","",Stage_ECL!K11) -> 0.009378193 | L11: =IF(Credit_Losses!B11="","",Credit_Losses!B11) -> 3190 | M11: =IF(Credit_Losses!C11="","",Credit_Losses!C11) -> 0.0147 | N11: =IF(Credit_Losses!G11="","",Credit_Losses!G11) -> 0.014342526 | O11: =IF(Credit_Losses!D11="","",Credit_Losses!D11) | P11: =IF(Capital!B11="","",Capital!B11) -> 0.2497 | Q11: =IF(Capital!C11="","",Capital!C11) -> 0.232 | R11: =IF(Capital!E11="","",Capital!E11) -> 5.1 | S11: =IF(Capital!I11="","",Capital!I11) | T11: =IF(Profitability!D11="","",Profitability!D11) -> 28858 | U11: =IF(Profitability!I11="","",Profitability!I11) -> 11508 | V11: =IF(Profitability!J11="","",Profitability!J11) -> 0.053 | W11: =IF(Profitability!K11="","",Profitability!K11) -> 0.2346 | X11: =IF(Profitability!M11="","",Profitability!M11) -> 0.35144501 | Y11: =IF(Profitability!N11="","",Profitability!N11) -> 0.11054127 | Z11: =IF(Liquidity!B11="","",Liquidity!B11) -> 11852 | AA11: =IF(Liquidity!C11="","",Liquidity!C11) | AB11: =IF(Liquidity!F11="","",Liquidity!F11) -> 0.21 | AC11: =IF(Liquidity!L11="","",Liquidity!L11) -> 0.93 | AD11: =IF(Liquidity!M11="","",Liquidity!M11) -> 0.31 | AE11: =IF(Profitability!L11="","",Profitability!L11) -> 0.0704
A12: FY2023-24 | B12: Bajaj Finance | C12: =IF(AUM!B12="","",AUM!B12) -> 330615 | D12: =IF(AUM!E12="","",AUM!E12) -> 0.33647157 | E12: =IF(Asset_Quality!B12="","",Asset_Quality!B12) -> 0.0085 | F12: =IF(Asset_Quality!C12="","",Asset_Quality!C12) -> 0.0037 | G12: =IF(Asset_Quality!D12="","",Asset_Quality!D12) -> 2816 | H12: =IF(Asset_Quality!E12="","",Asset_Quality!E12) -> 1210 | I12: =IF(Asset_Quality!F12="","",Asset_Quality!F12) -> 0.57 | J12: =IF(Stage_ECL!J12="","",Stage_ECL!J12) -> 0.012105609 | K12: =IF(Stage_ECL!K12="","",Stage_ECL!K12) -> 0.0084989769 | L12: =IF(Credit_Losses!B12="","",Credit_Losses!B12) -> 4631 | M12: =IF(Credit_Losses!C12="","",Credit_Losses!C12) -> 0.0163 | N12: =IF(Credit_Losses!G12="","",Credit_Losses!G12) -> 0.016024388 | O12: =IF(Credit_Losses!D12="","",Credit_Losses!D12) | P12: =IF(Capital!B12="","",Capital!B12) -> 0.2252 | Q12: =IF(Capital!C12="","",Capital!C12) -> 0.2151 | R12: =IF(Capital!E12="","",Capital!E12) -> 4.9 | S12: =IF(Capital!I12="","",Capital!I12) | T12: =IF(Profitability!D12="","",Profitability!D12) -> 36258 | U12: =IF(Profitability!I12="","",Profitability!I12) -> 14451 | V12: =IF(Profitability!J12="","",Profitability!J12) -> 0.0508 | W12: =IF(Profitability!K12="","",Profitability!K12) -> 0.2205 | X12: =IF(Profitability!M12="","",Profitability!M12) -> 0.33992498 | Y12: =IF(Profitability!N12="","",Profitability!N12) -> 0.12772354 | Z12: =IF(Liquidity!B12="","",Liquidity!B12) -> 15668 | AA12: =IF(Liquidity!C12="","",Liquidity!C12) -> 2.6 | AB12: =IF(Liquidity!F12="","",Liquidity!F12) -> 0.21 | AC12: =IF(Liquidity!L12="","",Liquidity!L12) -> 0.59 | AD12: =IF(Liquidity!M12="","",Liquidity!M12) -> 0.43 | AE12: =IF(Profitability!L12="","",Profitability!L12) -> 0.0774
A13: FY2024-25 | B13: Bajaj Finance | C13: =IF(AUM!B13="","",AUM!B13) -> 416661 | D13: =IF(AUM!E13="","",AUM!E13) -> 0.26026042 | E13: =IF(Asset_Quality!B13="","",Asset_Quality!B13) -> 0.0096 | F13: =IF(Asset_Quality!C13="","",Asset_Quality!C13) -> 0.0044 | G13: =IF(Asset_Quality!D13="","",Asset_Quality!D13) -> 3965 | H13: =IF(Asset_Quality!E13="","",Asset_Quality!E13) -> 1835 | I13: =IF(Asset_Quality!F13="","",Asset_Quality!F13) -> 0.54 | J13: =IF(Stage_ECL!J13="","",Stage_ECL!J13) -> 0.013027117 | K13: =IF(Stage_ECL!K13="","",Stage_ECL!K13) -> 0.0095582014 | L13: =IF(Credit_Losses!B13="","",Credit_Losses!B13) -> 7966 | M13: =IF(Credit_Losses!C13="","",Credit_Losses!C13) -> 0.0217 | N13: =IF(Credit_Losses!G13="","",Credit_Losses!G13) -> 0.021320101 | O13: =IF(Credit_Losses!D13="","",Credit_Losses!D13) | P13: =IF(Capital!B13="","",Capital!B13) -> 0.219 | Q13: =IF(Capital!C13="","",Capital!C13) -> 0.211 | R13: =IF(Capital!E13="","",Capital!E13) -> 4.7 | S13: =IF(Capital!I13="","",Capital!I13) | T13: =IF(Profitability!D13="","",Profitability!D13) -> 44954 | U13: =IF(Profitability!I13="","",Profitability!I13) -> 16779 | V13: =IF(Profitability!J13="","",Profitability!J13) -> 0.046 | W13: =IF(Profitability!K13="","",Profitability!K13) -> 0.192 | X13: =IF(Profitability!M13="","",Profitability!M13) -> 0.3320283 | Y13: =IF(Profitability!N13="","",Profitability!N13) -> 0.17720336 | Z13: =IF(Liquidity!B13="","",Liquidity!B13) -> 18757 | AA13: =IF(Liquidity!C13="","",Liquidity!C13) -> 2.88 | AB13: =IF(Liquidity!F13="","",Liquidity!F13) -> 0.2 | AC13: =IF(Liquidity!L13="","",Liquidity!L13) -> 0.56 | AD13: =IF(Liquidity!M13="","",Liquidity!M13) -> 0.57 | AE13: =IF(Profitability!L13="","",Profitability!L13) -> 0.0797
A14: FY2025-26 | B14: Bajaj Finance | C14: =IF(AUM!B14="","",AUM!B14) -> 509975 | D14: =IF(AUM!E14="","",AUM!E14) -> 0.22395665 | E14: =IF(Asset_Quality!B14="","",Asset_Quality!B14) -> 0.0101 | F14: =IF(Asset_Quality!C14="","",Asset_Quality!C14) -> 0.0041 | G14: =IF(Asset_Quality!D14="","",Asset_Quality!D14) -> 5119 | H14: =IF(Asset_Quality!E14="","",Asset_Quality!E14) -> 2062 | I14: =IF(Asset_Quality!F14="","",Asset_Quality!F14) -> 0.6 | J14: =IF(Stage_ECL!J14="","",Stage_ECL!J14) -> 0.0093589713 | K14: =IF(Stage_ECL!K14="","",Stage_ECL!K14) -> 0.010052156 | L14: =IF(Credit_Losses!B14="","",Credit_Losses!B14) -> 10282 | M14: =IF(Credit_Losses!C14="","",Credit_Losses!C14) -> 0.0227 | N14: =IF(Credit_Losses!G14="","",Credit_Losses!G14) -> 0.022192101 | O14: =IF(Credit_Losses!D14="","",Credit_Losses!D14) | P14: =IF(Capital!B14="","",Capital!B14) -> 0.2155 | Q14: =IF(Capital!C14="","",Capital!C14) -> 0.2067 | R14: =IF(Capital!E14="","",Capital!E14) -> 4.8 | S14: =IF(Capital!I14="","",Capital!I14) | T14: =IF(Profitability!D14="","",Profitability!D14) -> 54123 | U14: =IF(Profitability!I14="","",Profitability!I14) -> 19332 | V14: =IF(Profitability!J14="","",Profitability!J14) -> 0.043 | W14: =IF(Profitability!K14="","",Profitability!K14) -> 0.181 | X14: =IF(Profitability!M14="","",Profitability!M14) -> 0.32843708 | Y14: =IF(Profitability!N14="","",Profitability!N14) -> 0.18997469 | Z14: =IF(Liquidity!B14="","",Liquidity!B14) -> 15020 | AA14: =IF(Liquidity!C14="","",Liquidity!C14) -> 2.28 | AB14: =IF(Liquidity!F14="","",Liquidity!F14) -> 0.16 | AC14: =IF(Liquidity!L14="","",Liquidity!L14) -> 0.36 | AD14: =IF(Liquidity!M14="","",Liquidity!M14) -> 0.49 | AE14: =IF(Profitability!L14="","",Profitability!L14) -> 0.0754
A16: Blank cell = not yet collected (yellow in the topic sheet). FY2016-17 is pre-Ind AS (no stage/ECL data). FY2019-20 is the pre-COVID base year.

Sheet Formulas_Guide
A1: Formulas guide — every calculated column, what it does and why
A2: t = current year, t−1 = previous year. 'Excel formula' shows the actual formula in the FY2025-26 row (other years use the same formula shifted to their row).
A4: # | B4: Sheet | C4: Column | D4: Plain-English formula | E4: Why it is there | F4: Excel formula (FY2025-26 row) | G4: Cell
A5: 1 | B5: AUM | C5: AUM growth % | D5: AUM(t) ÷ AUM(t−1) − 1 | E5: Loan growth: Graph 1 and the X-axis of the growth-vs-risk scatter. | F5: =B14/B13-1 | G5: AUM!E14
A6: 2 | B6: AUM | C6: AUM added in year | D6: AUM(t) − AUM(t−1) | E6: Absolute expansion in ₹ crore, as the company reports it. | F6: =B14-B13 | G6: AUM!F14
A7: 3 | B7: AUM | C7: Average AUM | D7: (AUM(t) + AUM(t−1)) ÷ 2 | E7: Denominator for credit cost; avoids distortion from fast growth. | F7: =AVERAGE(B14,B13) | G7: AUM!G14
A8: 4 | B8: AUM | C8: Housing/other subs share of AUM | D8: 1 − Standalone AUM ÷ Consolidated AUM | E8: Share of the book held in subsidiaries (mainly Bajaj Housing Finance). | F8: =IF(OR(C14=""),"",1-C14/B14) | G8: AUM!H14
A9: 5 | B9: Segment_AUM | C9: Share of AUM | D9: Segment AUM ÷ total AUM of that block | E9: Product-mix percentages for Graph 8. | F9: =D5/SUM($D$5:$D$9) | G9: Segment_AUM!E5
A10: 6 | B10: Segment_AUM | C10: Total (each block) | D10: SUM of segment AUM | E10: Check: equals reported total AUM every year. | F10: =SUM(D5:D9) | G10: Segment_AUM!D10
A11: 7 | B11: Segment_AUM | C11: Broad mix (5 buckets) | D11: Sum of segments in each group ÷ total | E11: Puts differently-named segments on one consistent basis across years. | F11: =(D109+D110+D111+D112)/(D109+D110+D111+D112+D113+D114+D115+D116+D117+D119+D118+D120+D121+D122) | G11: Segment_AUM!B136
A12: 8 | B12: Segment_AUM | C12: Mix total | D12: SUM of the 5 buckets | E12: Check: must equal 100%. | F12: =IF(COUNT(B136:F136)=5,SUM(B136:F136),"") | G12: Segment_AUM!G136
A13: 9 | B13: Asset_Quality | C13: PCR % (calc: 1 − Net/Gross NPA) | D13: 1 − Net NPA ÷ Gross NPA | E13: Independent check of reported provision coverage. | F13: =IF(OR(D14="",E14=""),"",1-E14/D14) | G13: Asset_Quality!G14
A14: 10 | B14: Asset_Quality | C14: Change in GNPA (pp) | D14: GNPA %(t) − GNPA %(t−1) | E14: Whether asset quality improved or worsened each year. | F14: =B14-B13 | G14: Asset_Quality!H14
A15: 11 | B15: Stage_ECL | C15: Total gross loans | D15: Stage 1 + Stage 2 + Stage 3 | E15: Denominator for stage shares (only when all three exist). | F15: =IF(COUNT(B14:D14)<3,"",SUM(B14:D14)) | G15: Stage_ECL!H14
A16: 12 | B16: Stage_ECL | C16: Total ECL | D16: ECL S1 + ECL S2 + ECL S3 | E16: Closing loss allowance — the ECL variable. | F16: =IF(COUNT(E14:G14)<3,"",SUM(E14:G14)) | G16: Stage_ECL!I14
... A38: 34 | B38: Master_Dataset | C38: Every column | D38: =IF(source cell="","",source cell) | E38: Pulls all variables into one table; keeps blanks blank (not 0) so missing years don't distort graphs or correlations. | F38: =IF(AUM!B14="","",AUM!B14) | G38: Master_Dataset!C14
A39: 35 | B39: All sheets | C39: Blank guard | D39: IF(OR(input="", …), "", calculation) | E39: If an input is missing, the result stays blank instead of an error or misleading number.
A40: 36 | B40: All sheets | C40: Completeness guard | D40: IF(COUNT(range)<n, "", SUM(range)) | E40: Totals (loans, ECL) calculate only when every component is present.

Sheet AUM
A1: Assets under management (₹ crore)
A2: Consolidated AUM is the headline figure. Standalone = Bajaj Finance Ltd alone (excludes housing subsidiary).
A4: Financial year | B4: Consolidated AUM | C4: Standalone AUM | D4: Assets under finance (AUF) | E4: AUM growth % | F4: AUM added in year | G4: Average AUM | H4: Housing/other subs share of AUM | I4: Source
A5: FY2016-17 | B5: 60196 | C5: 60196 | H5: =IF(OR(C5=""),"",1-C5/B5) -> 0 | I5: FY26 deck sl.35 (IGAAP, standalone basis)
A6: FY2017-18 | B6: 82422 | C6: 78852 | D6: 80633 | E6: =B6/B5-1 -> 0.36922719 | F6: =B6-B5 -> 22226 | G6: =AVERAGE(B6,B5) -> 71309 | H6: =IF(OR(C6=""),"",1-C6/B6) -> 0.043313678 | I6: FY26 deck sl.35; FY20 AR p.12, 248
A7: FY2018-19 | B7: 115888 | C7: 98671 | D7: 114570 | E7: =B7/B6-1 -> 0.40603237 | F7: =B7-B6 -> 33466 | G7: =AVERAGE(B7,B6) -> 99155 | H7: =IF(OR(C7=""),"",1-C7/B7) -> 0.14856586 | I7: FY20 AR p.12-13, 248
A8: FY2019-20 | B8: 147153 | C8: 116102 | D8: 145100 | E8: =B8/B7-1 -> 0.26978635 | F8: =B8-B7 -> 31265 | G8: =AVERAGE(B8,B7) -> 131520.5 | H8: =IF(OR(C8=""),"",1-C8/B8) -> 0.21101167 | I8: FY20 AR p.13, 247
A9: FY2020-21 | B9: 152947 | C9: 115418 | D9: 150995 | E9: =B9/B8-1 -> 0.039373985 | F9: =B9-B8 -> 5794 | G9: =AVERAGE(B9,B8) -> 150050 | H9: =IF(OR(C9=""),"",1-C9/B9) -> 0.24537258 | I9: FY21 AR p.13, 20, 259
A10: FY2021-22 | B10: 197452 | D10: 195828 | E10: =B10/B9-1 -> 0.29098315 | F10: =B10-B9 -> 44505 | G10: =AVERAGE(B10,B9) -> 175199.5 | H10: =IF(OR(C10=""),"",1-C10/B10) | I10: FY22 AR p.19, 26, 315
A11: FY2022-23 | B11: 247379 | C11: 180999 | D11: 242269 | E11: =B11/B10-1 -> 0.25285639 | F11: =B11-B10 -> 49927 | G11: =AVERAGE(B11,B10) -> 222415.5 | H11: =IF(OR(C11=""),"",1-C11/B11) -> 0.26833321 | I11: FY24 deck sl.38-39
A12: FY2023-24 | B12: 330615 | C12: 244826 | D12: 326293 | E12: =B12/B11-1 -> 0.33647157 | F12: =B12-B11 -> 83236 | G12: =AVERAGE(B12,B11) -> 288997 | H12: =IF(OR(C12=""),"",1-C12/B12) -> 0.25948308 | I12: FY24 deck sl.38-39
A13: FY2024-25 | B13: 416661 | C13: 308832 | D13: 407844 | E13: =B13/B12-1 -> 0.26026042 | F13: =B13-B12 -> 86046 | G13: =AVERAGE(B13,B12) -> 373638 | H13: =IF(OR(C13=""),"",1-C13/B13) -> 0.25879312 | I13: FY26 deck sl.44-46
A14: FY2025-26 | B14: 509975 | C14: 372986 | D14: 498944 | E14: =B14/B13-1 -> 0.22395665 | F14: =B14-B13 -> 93314 | G14: =AVERAGE(B14,B13) -> 463318 | H14: =IF(OR(C14=""),"",1-C14/B14) -> 0.26861905 | I14: FY26 deck sl.44-46
A16: FY20–FY22 AUF = gross term loans from Note 9 (Loans). FY22 standalone AUM: MD&A of FY22 annual report (not yet collected).

Sheet Segment_AUM
A1: Segment-wise consolidated AUM and segment GNPA (₹ crore)
A2: Bajaj re-named its segments over time, so each classification is a separate block. Compare within a block; use the broad mix at the bottom for a long view.
A4: Block | B4: As of | C4: Segment | D4: AUM (₹ cr) | E4: Share of AUM | F4: Segment GNPA % | G4: Secured / Unsecured | H4: Risk tier (your view) | I4: Why | J4: Source
A5: 0: FY18 deck (IGAAP, 5 buckets; mortgages inside) | B5: 31-Mar-2017 | C5: Consumer B2B | D5: 13181 | E5: =D5/SUM($D$5:$D$9) -> 0.21896804 | G5: Mostly unsecured / 2W | H5: Medium–High | I5: Consumer durable EMI and 2W/3W loans | J5: Q4FY18 deck p.15
A6: 0: FY18 deck (IGAAP, 5 buckets; mortgages inside) | B6: 31-Mar-2017 | C6: Consumer B2C | D6: 13978 | E6: =D6/SUM($D$5:$D$9) -> 0.23220812 | G6: Unsecured | H6: High | I6: Personal loans | J6: Q4FY18 deck p.15
A7: 0: FY18 deck (IGAAP, 5 buckets; mortgages inside) | B7: 31-Mar-2017 | C7: SME | D7: 22082 | E7: =D7/SUM($D$5:$D$9) -> 0.36683501 | G7: Mostly unsecured (incl. LAP) | H7: High | I7: Unsecured business loans; LAP inside | J7: Q4FY18 deck p.15
A8: 0: FY18 deck (IGAAP, 5 buckets; mortgages inside) | B8: 31-Mar-2017 | C8: Commercial | D8: 7883 | E8: =D8/SUM($D$5:$D$9) -> 0.13095555 | G8: Secured / corporate | H8: Low | I8: Corporate and securities lending | J8: Q4FY18 deck p.15
A9: 0: FY18 deck (IGAAP, 5 buckets; mortgages inside) | B9: 31-Mar-2017 | C9: Rural | D9: 3072 | E9: =D9/SUM($D$5:$D$9) -> 0.051033291 | G9: Mostly unsecured | H9: High | I9: Rural consumer and personal loans | J9: Q4FY18 deck p.15
C10: Total | D10: =SUM(D5:D9) -> 60196
A12: 0: FY18 deck (IGAAP, 5 buckets; mortgages inside) | B12: 31-Mar-2018 | C12: Consumer B2B | D12: 16381 | E12: =D12/SUM($D$12:$D$16) -> 0.19493532 | G12: Mostly unsecured / 2W | H12: Medium–High | I12: Consumer durable EMI and 2W/3W loans | J12: Q4FY18 deck p.15, 26
A13: 0: FY18 deck (IGAAP, 5 buckets; mortgages inside) | B13: 31-Mar-2018 | C13: Consumer B2C | D13: 22780 | E13: =D13/SUM($D$12:$D$16) -> 0.27108398 | G13: Unsecured | H13: High | I13: Personal loans | J13: Q4FY18 deck p.15, 26
A14: 0: FY18 deck (IGAAP, 5 buckets; mortgages inside) | B14: 31-Mar-2018 | C14: SME | D14: 26366 | E14: =D14/SUM($D$12:$D$16) -> 0.31375769 | F14: 0.0131 | G14: Mostly unsecured (incl. LAP) | H14: High | I14: Unsecured business loans; LAP inside | J14: Q4FY18 deck p.15, 26
A15: 0: FY18 deck (IGAAP, 5 buckets; mortgages inside) | B15: 31-Mar-2018 | C15: Commercial | D15: 12375 | E15: =D15/SUM($D$12:$D$16) -> 0.14726358 | F15: 0.0002 | G15: Secured / corporate | H15: Low | I15: Corporate and securities lending | J15: Q4FY18 deck p.15, 26
A16: 0: FY18 deck (IGAAP, 5 buckets; mortgages inside) | B16: 31-Mar-2018 | C16: Rural | D16: 6131 | E16: =D16/SUM($D$12:$D$16) -> 0.072959433 | F16: 0.0117 | G16: Mostly unsecured | H16: High | I16: Rural consumer and personal loans | J16: Q4FY18 deck p.15, 26
C17: Total | D17: =SUM(D12:D16) -> 84033
A19: A: FY20–FY22 AR classification | B19: 31-Mar-2019 | C19: Consumer B2B – auto finance (2W/3W) | D19: 9726 | E19: =D19/SUM($D$19:$D$28) -> 0.083925859 | G19: Secured (vehicle) | H19: High | I19: 2W/3W loans to lower-income borrowers; depreciating collateral | J19: FY20 AR p.13
A20: A: FY20–FY22 AR classification | B20: 31-Mar-2019 | C20: Consumer B2B – sales finance | D20: 12261 | E20: =D20/SUM($D$19:$D$28) -> 0.10580043 | G20: Unsecured | H20: Medium | I20: Short-tenor consumer-durable EMI loans | J20: FY20 AR p.13
A21: A: FY20–FY22 AR classification | B21: 31-Mar-2019 | C21: Consumer B2C (personal loans) | D21: 23002 | E21: =D21/SUM($D$19:$D$28) -> 0.19848474 | G21: Unsecured | H21: High | I21: Unsecured personal loans | J21: FY20 AR p.13
A22: A: FY20–FY22 AR classification | B22: 31-Mar-2019 | C22: SME business | D22: 15759 | E22: =D22/SUM($D$19:$D$28) -> 0.13598474 | G22: Mostly unsecured | H22: High | I22: Unsecured working-capital loans to small businesses | J22: FY20 AR p.13
A23: A: FY20–FY22 AR classification | B23: 31-Mar-2019 | C23: Rural B2B – sales finance | D23: 2142 | E23: =D23/SUM($D$19:$D$28) -> 0.018483363 | G23: Unsecured | H23: Medium | I23: Short-tenor consumer-durable loans, rural | J23: FY20 AR p.13
A24: A: FY20–FY22 AR classification | B24: 31-Mar-2019 | C24: Rural B2C | D24: 7101 | E24: =D24/SUM($D$19:$D$28) -> 0.061274679 | G24: Unsecured | H24: High | I24: Unsecured rural personal/business loans | J24: FY20 AR p.13
A25: A: FY20–FY22 AR classification | B25: 31-Mar-2019 | C25: Commercial Lending | D25: 5668 | E25: =D25/SUM($D$19:$D$28) -> 0.048909292 | G25: Secured / corporate | H25: Low | I25: Mid-corporate lending; GNPA <0.3% | J25: FY20 AR p.13
A26: A: FY20–FY22 AR classification | B26: 31-Mar-2019 | C26: Loans against securities | D26: 6359 | E26: =D26/SUM($D$19:$D$28) -> 0.054871945 | G26: Secured (securities) | H26: Low | I26: Marked-to-market collateral | J26: FY20 AR p.13
A27: A: FY20–FY22 AR classification | B27: 31-Mar-2019 | C27: IPO financing | D27: 0 | E27: =D27/SUM($D$19:$D$28) -> 0 | G27: Secured (securities) | H27: Low | I27: Very short-tenor; balance at year-end only | J27: FY20 AR p.13
A28: A: FY20–FY22 AR classification | B28: 31-Mar-2019 | C28: Mortgages | D28: 33870 | E28: =D28/SUM($D$19:$D$28) -> 0.29226495 | G28: Secured (property) | H28: Low | I28: Home loans, LAP, LRD; GNPA ~0.5% | J28: FY20 AR p.13
C29: Total | D29: =SUM(D19:D28) -> 115888
A31: A: FY20–FY22 AR classification | B31: 31-Mar-2020 | C31: Consumer B2B – auto finance (2W/3W) | D31: 13085 | E31: =D31/SUM($D$31:$D$40) -> 0.088921055 | G31: Secured (vehicle) | H31: High | I31: 2W/3W loans to lower-income borrowers; depreciating collateral | J31: FY20 AR p.13
A32: A: FY20–FY22 AR classification | B32: 31-Mar-2020 | C32: Consumer B2B – sales finance | D32: 12657 | E32: =D32/SUM($D$31:$D$40) -> 0.086012518 | G32: Unsecured | H32: Medium | I32: Short-tenor consumer-durable EMI loans | J32: FY20 AR p.13
A33: A: FY20–FY22 AR classification | B33: 31-Mar-2020 | C33: Consumer B2C (personal loans) | D33: 31256 | E33: =D33/SUM($D$31:$D$40) -> 0.21240478 | G33: Unsecured | H33: High | I33: Unsecured personal loans | J33: FY20 AR p.13
A34: A: FY20–FY22 AR classification | B34: 31-Mar-2020 | C34: SME business | D34: 19429 | E34: =D34/SUM($D$31:$D$40) -> 0.13203265 | G34: Mostly unsecured | H34: High | I34: Unsecured working-capital loans to small businesses | J34: FY20 AR p.13
A35: A: FY20–FY22 AR classification | B35: 31-Mar-2020 | C35: Rural B2B – sales finance | D35: 2669 | E35: =D35/SUM($D$31:$D$40) -> 0.018137585 | G35: Unsecured | H35: Medium | I35: Short-tenor consumer-durable loans, rural | J35: FY20 AR p.13
A36: A: FY20–FY22 AR classification | B36: 31-Mar-2020 | C36: Rural B2C | D36: 10659 | E36: =D36/SUM($D$31:$D$40) -> 0.072434813 | G36: Unsecured | H36: High | I36: Unsecured rural personal/business loans | J36: FY20 AR p.13
A37: A: FY20–FY22 AR classification | B37: 31-Mar-2020 | C37: Commercial Lending | D37: 6411 | E37: =D37/SUM($D$31:$D$40) -> 0.0435669 | G37: Secured / corporate | H37: Low | I37: Mid-corporate lending; GNPA <0.3% | J37: FY20 AR p.13
A38: A: FY20–FY22 AR classification | B38: 31-Mar-2020 | C38: Loans against securities | D38: 4821 | E38: =D38/SUM($D$31:$D$40) -> 0.032761819 | G38: Secured (securities) | H38: Low | I38: Marked-to-market collateral | J38: FY20 AR p.13
A39: A: FY20–FY22 AR classification | B39: 31-Mar-2020 | C39: IPO financing | D39: 0 | E39: =D39/SUM($D$31:$D$40) -> 0 | G39: Secured (securities) | H39: Low | I39: Very short-tenor; balance at year-end only | J39: FY20 AR p.13
A40: A: FY20–FY22 AR classification | B40: 31-Mar-2020 | C40: Mortgages | D40: 46166 | E40: =D40/SUM($D$31:$D$40) -> 0.31372789 | G40: Secured (property) | H40: Low | I40: Home loans, LAP, LRD; GNPA ~0.5% | J40: FY20 AR p.13
C41: Total | D41: =SUM(D31:D40) -> 147153
A43: A: FY20–FY22 AR classification | B43: 31-Mar-2021 | C43: Consumer B2B – auto finance (2W/3W) | D43: 12111 | E43: =D43/SUM($D$43:$D$52) -> 0.079184293 | G43: Secured (vehicle) | H43: High | I43: 2W/3W loans to lower-income borrowers; depreciating collateral | J43: FY21 AR p.20
A44: A: FY20–FY22 AR classification | B44: 31-Mar-2021 | C44: Consumer B2B – sales finance | D44: 11526 | E44: =D44/SUM($D$43:$D$52) -> 0.075359438 | G44: Unsecured | H44: Medium | I44: Short-tenor consumer-durable EMI loans | J44: FY21 AR p.20
A45: A: FY20–FY22 AR classification | B45: 31-Mar-2021 | C45: Consumer B2C (personal loans) | D45: 30450 | E45: =D45/SUM($D$43:$D$52) -> 0.19908857 | G45: Unsecured | H45: High | I45: Unsecured personal loans | J45: FY21 AR p.20
...

Sheet Asset_Quality
A1: Asset quality — NPAs and provision coverage
A2: Gross NPA ₹ = Stage 3 gross loans; Net NPA ₹ = Stage 3 less Stage 3 ECL. Ratios as reported by the company.
A4: Financial year | B4: GNPA % (reported) | C4: NNPA % (reported) | D4: Gross NPA ₹ (Stage 3) | E4: Net NPA ₹ | F4: PCR on Stage 3 % (reported) | G4: PCR % (calc: 1 − Net/Gross NPA) | H4: Change in GNPA (pp) | I4: Source
A5: FY2016-17 | B5: 0.0168 | C5: 0.0044 | F5: 0.74 | G5: =IF(OR(D5="",E5=""),"",1-E5/D5) | I5: Q4FY18 deck p.11 (IGAAP, 4-months overdue)
A6: FY2017-18 | B6: 0.0141 | C6: 0.0043 | D6: 1200 | E6: 390 | F6: 0.7 | G6: =IF(OR(D6="",E6=""),"",1-E6/D6) -> 0.675 | H6: =B6-B5 -> -0.0027 | I6: Q3FY19 deck sl.45; FY20 AR p.248
A7: FY2018-19 | B7: 0.0154 | C7: 0.0063 | D7: 1812 | E7: 735 | F7: 0.6 | G7: =IF(OR(D7="",E7=""),"",1-E7/D7) -> 0.59437086 | H7: =B7-B6 -> 0.0013 | I7: FY20 AR p.28, 247
A8: FY2019-20 | B8: 0.0161 | C8: 0.0065 | D8: 2363 | E8: 938 | F8: 0.6 | G8: =IF(OR(D8="",E8=""),"",1-E8/D8) -> 0.60304697 | H8: =B8-B7 -> 0.0007 | I8: FY20 AR p.28, p.247
A9: FY2020-21 | B9: 0.0179 | C9: 0.0075 | D9: 2731 | E9: 1136 | F9: 0.58 | G9: =IF(OR(D9="",E9=""),"",1-E9/D9) -> 0.58403515 | H9: =B9-B8 -> 0.0018 | I9: FY21 AR p.21, 259
A10: FY2021-22 | B10: 0.016 | C10: 0.0068 | D10: 3133 | E10: 1315 | F10: 0.58 | G10: =IF(OR(D10="",E10=""),"",1-E10/D10) -> 0.5802745 | H10: =B10-B9 -> -0.0019 | I10: FY22 AR p.28, 315
A11: FY2022-23 | B11: 0.0094 | C11: 0.0034 | D11: 2313 | E11: 837 | F11: 0.64 | G11: =IF(OR(D11="",E11=""),"",1-E11/D11) -> 0.6381323 | H11: =B11-B10 -> -0.0066 | I11: FY24 deck sl.58-59
A12: FY2023-24 | B12: 0.0085 | C12: 0.0037 | D12: 2816 | E12: 1210 | F12: 0.57 | G12: =IF(OR(D12="",E12=""),"",1-E12/D12) -> 0.5703125 | H12: =B12-B11 -> -0.0009 | I12: FY24 deck sl.58-59
A13: FY2024-25 | B13: 0.0096 | C13: 0.0044 | D13: 3965 | E13: 1835 | F13: 0.54 | G13: =IF(OR(D13="",E13=""),"",1-E13/D13) -> 0.5372005 | H13: =B13-B12 -> 0.0011 | I13: FY26 deck sl.66-67
A14: FY2025-26 | B14: 0.0101 | C14: 0.0041 | D14: 5119 | E14: 2062 | F14: 0.6 | G14: =IF(OR(D14="",E14=""),"",1-E14/D14) -> 0.59718695 | H14: =B14-B13 -> 0.0005 | I14: FY26 deck sl.66-67
A16: Gross NPA ₹ = Stage 3 gross and Net NPA ₹ = Stage 3 net carrying amount, from Note 9 (Loans) / company decks.

Sheet Stage_ECL
A1: Stage-wise loans and expected credit loss (ECL) allowance (₹ crore)
A2: Stage 1 = performing; Stage 2 = significant increase in credit risk (31–90 dpd); Stage 3 = credit-impaired (NPA).
A4: Financial year | B4: Stage 1 gross | C4: Stage 2 gross | D4: Stage 3 gross | E4: ECL Stage 1 | F4: ECL Stage 2 | G4: ECL Stage 3 | H4: Total gross loans | I4: Total ECL | J4: Stage 2 % of loans | K4: Stage 3 % of loans | L4: ECL cover on Stage 1+2 | M4: ECL cover on Stage 3 | N4: Total ECL / loans | O4: Source
A5: FY2016-17 | H5: =IF(COUNT(B5:D5)<3,"",SUM(B5:D5)) | I5: =IF(COUNT(E5:G5)<3,"",SUM(E5:G5)) | J5: =IF(OR(H5=""),"",C5/H5) | K5: =IF(OR(H5=""),"",D5/H5) | L5: =IF(OR(H5="",I5=""),"",(E5+F5)/(B5+C5)) | M5: =IF(OR(D5="",G5=""),"",G5/D5) | N5: =IF(OR(H5="",I5=""),"",I5/H5) | O5: Pre-Ind AS: no stages
A6: FY2017-18 | B6: 78351 | C6: 1082 | D6: 1200 | E6: 468 | F6: 252 | G6: 810 | H6: =IF(COUNT(B6:D6)<3,"",SUM(B6:D6)) -> 80633 | I6: =IF(COUNT(E6:G6)<3,"",SUM(E6:G6)) -> 1530 | J6: =IF(OR(H6=""),"",C6/H6) -> 0.013418824 | K6: =IF(OR(H6=""),"",D6/H6) -> 0.014882244 | L6: =IF(OR(H6="",I6=""),"",(E6+F6)/(B6+C6)) -> 0.0090642428 | M6: =IF(OR(D6="",G6=""),"",G6/D6) -> 0.675 | N6: =IF(OR(H6="",I6=""),"",I6/H6) -> 0.018974861 | O6: FY20 AR p.248 (opening balance)
A7: FY2018-19 | B7: 110748 | C7: 2011 | D7: 1812 | E7: 619 | F7: 362 | G7: 1077 | H7: =IF(COUNT(B7:D7)<3,"",SUM(B7:D7)) -> 114571 | I7: =IF(COUNT(E7:G7)<3,"",SUM(E7:G7)) -> 2058 | J7: =IF(OR(H7=""),"",C7/H7) -> 0.017552435 | K7: =IF(OR(H7=""),"",D7/H7) -> 0.015815521 | L7: =IF(OR(H7="",I7=""),"",(E7+F7)/(B7+C7)) -> 0.0086999707 | M7: =IF(OR(D7="",G7=""),"",G7/D7) -> 0.59437086 | N7: =IF(OR(H7="",I7=""),"",I7/H7) -> 0.017962661 | O7: FY20 AR p.247-248
A8: FY2019-20 | B8: 139589 | C8: 3148 | D8: 2363 | E8: 1712 | F8: 587 | G8: 1425 | H8: =IF(COUNT(B8:D8)<3,"",SUM(B8:D8)) -> 145100 | I8: =IF(COUNT(E8:G8)<3,"",SUM(E8:G8)) -> 3724 | J8: =IF(OR(H8=""),"",C8/H8) -> 0.021695382 | K8: =IF(OR(H8=""),"",D8/H8) -> 0.01628532 | L8: =IF(OR(H8="",I8=""),"",(E8+F8)/(B8+C8)) -> 0.016106546 | M8: =IF(OR(D8="",G8=""),"",G8/D8) -> 0.60304697 | N8: =IF(OR(H8="",I8=""),"",I8/H8) -> 0.025665059 | O8: FY20 AR p.247 (Note 9)
A9: FY2020-21 | B9: 141539 | C9: 6725 | D9: 2731 | E9: 1146 | F9: 1567 | G9: 1595 | H9: =IF(COUNT(B9:D9)<3,"",SUM(B9:D9)) -> 150995 | I9: =IF(COUNT(E9:G9)<3,"",SUM(E9:G9)) -> 4308 | J9: =IF(OR(H9=""),"",C9/H9) -> 0.044537899 | K9: =IF(OR(H9=""),"",D9/H9) -> 0.018086692 | L9: =IF(OR(H9="",I9=""),"",(E9+F9)/(B9+C9)) -> 0.018298441 | M9: =IF(OR(D9="",G9=""),"",G9/D9) -> 0.58403515 | N9: =IF(OR(H9="",I9=""),"",I9/H9) -> 0.028530746 | O9: FY21 AR p.259 (Note 9)
A10: FY2021-22 | B10: 188834 | C10: 3861 | D10: 3133 | E10: 1507 | F10: 1079 | G10: 1819 | H10: =IF(COUNT(B10:D10)<3,"",SUM(B10:D10)) -> 195828 | I10: =IF(COUNT(E10:G10)<3,"",SUM(E10:G10)) -> 4405 | J10: =IF(OR(H10=""),"",C10/H10) -> 0.019716282 | K10: =IF(OR(H10=""),"",D10/H10) -> 0.015998734 | L10: =IF(OR(H10="",I10=""),"",(E10+F10)/(B10+C10)) -> 0.013420172 | M10: =IF(OR(D10="",G10=""),"",G10/D10) -> 0.58059368 | N10: =IF(OR(H10="",I10=""),"",I10/H10) -> 0.02249423 | O10: FY22 AR p.315 (Note 9)
A11: FY2022-23 | B11: 241290 | C11: 3033 | D11: 2313 | E11: 1957 | F11: 933 | G11: 1476 | H11: =IF(COUNT(B11:D11)<3,"",SUM(B11:D11)) -> 246636 | I11: =IF(COUNT(E11:G11)<3,"",SUM(E11:G11)) -> 4366 | J11: =IF(OR(H11=""),"",C11/H11) -> 0.012297475 | K11: =IF(OR(H11=""),"",D11/H11) -> 0.009378193 | L11: =IF(OR(H11="",I11=""),"",(E11+F11)/(B11+C11)) -> 0.011828604 | M11: =IF(OR(D11="",G11=""),"",G11/D11) -> 0.6381323 | N11: =IF(OR(H11="",I11=""),"",I11/H11) -> 0.017702201 | O11: FY24 deck sl.59
A12: FY2023-24 | B12: 324507 | C12: 4011 | D12: 2816 | E12: 2245 | F12: 1190 | G12: 1606 | H12: =IF(COUNT(B12:D12)<3,"",SUM(B12:D12)) -> 331334 | I12: =IF(COUNT(E12:G12)<3,"",SUM(E12:G12)) -> 5041 | J12: =IF(OR(H12=""),"",C12/H12) -> 0.012105609 | K12: =IF(OR(H12=""),"",D12/H12) -> 0.0084989769 | L12: =IF(OR(H12="",I12=""),"",(E12+F12)/(B12+C12)) -> 0.010456048 | M12: =IF(OR(D12="",G12=""),"",G12/D12) -> 0.5703125 | N12: =IF(OR(H12="",I12=""),"",I12/H12) -> 0.015214255 | O12: FY24 deck sl.59
A13: FY2024-25 | B13: 405458 | C13: 5404 | D13: 3965 | E13: 3104 | F13: 1749 | G13: 2130 | H13: =IF(COUNT(B13:D13)<3,"",SUM(B13:D13)) -> 414827 | I13: =IF(COUNT(E13:G13)<3,"",SUM(E13:G13)) -> 6983 | J13: =IF(OR(H13=""),"",C13/H13) -> 0.013027117 | K13: =IF(OR(H13=""),"",D13/H13) -> 0.0095582014 | L13: =IF(OR(H13="",I13=""),"",(E13+F13)/(B13+C13)) -> 0.011811752 | M13: =IF(OR(D13="",G13=""),"",G13/D13) -> 0.5372005 | N13: =IF(OR(H13="",I13=""),"",I13/H13) -> 0.016833523 | O13: FY26 deck sl.67
A14: FY2025-26 | B14: 499359 | C14: 4766 | D14: 5119 | E14: 5088 | F14: 2155 | G14: 3057 | H14: =IF(COUNT(B14:D14)<3,"",SUM(B14:D14)) -> 509244 | I14: =IF(COUNT(E14:G14)<3,"",SUM(E14:G14)) -> 10300 | J14: =IF(OR(H14=""),"",C14/H14) -> 0.0093589713 | K14: =IF(OR(H14=""),"",D14/H14) -> 0.010052156 | L14: =IF(OR(H14="",I14=""),"",(E14+F14)/(B14+C14)) -> 0.014367468 | M14: =IF(OR(D14="",G14=""),"",G14/D14) -> 0.59718695 | N14: =IF(OR(H14="",I14=""),"",I14/H14) -> 0.020226061 | O14: FY26 deck sl.67
A16: FY20–FY22 from 'Summary of loans by stage distribution', Note 9, consolidated financial statements. FY21 Stage 2 jump reflects COVID-19 stress and restructuring.

Sheet Credit_Losses
A1: Credit losses — loan-loss provisions, credit cost and write-offs (₹ crore)
A2: Original presentation basis (before FY26 reclassification of recoveries). Restated: FY25 ₹7,088 cr / 1.93%; FY26 ₹9,482 cr / 2.09%.
A4: Financial year | B4: Loan losses & provisions (impairment) | C4: Credit cost % (reported: loss / avg AUF) | D4: Write-offs | E4: One-time / overlay provisions in year | F4: Loan losses excl. one-time | G4: Credit cost % (calc: loss / avg AUM) | H4: Growth in loan losses % | I4: Source
A5: FY2016-17 | B5: 804 | C5: 0.0161 | F5: =B5-N(E5) -> 804 | I5: FY26 deck sl.35
A6: FY2017-18 | B6: 1030 | C6: 0.015 | F6: =B6-N(E6) -> 1030 | G6: =B6/AUM!G6 -> 0.01444418 | H6: =B6/B5-1 -> 0.28109453 | I6: FY26 deck sl.35
A7: FY2018-19 | B7: 1501 | C7: 0.0155 | D7: 965 | F7: =B7-N(E7) -> 1501 | G7: =B7/AUM!G7 -> 0.015137915 | H7: =B7/B6-1 -> 0.45728155 | I7: FY20 AR p.28, 248-249
A8: FY2019-20 | B8: 3929 | C8: 0.031 | D8: 2248 | E8: 900 | F8: =B8-N(E8) -> 3029 | G8: =B8/AUM!G8 -> 0.02987367 | H8: =B8/B7-1 -> 1.6175883 | I8: FY20 AR p.11, 248-249
A9: FY2020-21 | B9: 5969 | C9: 0.0414 | D9: 5554 | F9: =B9-N(E9) -> 5969 | G9: =B9/AUM!G9 -> 0.039780073 | H9: =B9/B8-1 -> 0.51921609 | I9: FY21 AR p.13, 260-261
A10: FY2021-22 | B10: 4803 | C10: 0.0284 | D10: 4807 | F10: =B10-N(E10) -> 4803 | G10: =B10/AUM!G10 -> 0.027414462 | H10: =B10/B9-1 -> -0.1953426 | I10: FY22 AR p.19, 315-316
A11: FY2022-23 | B11: 3190 | C11: 0.0147 | F11: =B11-N(E11) -> 3190 | G11: =B11/AUM!G11 -> 0.014342526 | H11: =B11/B10-1 -> -0.33583177 | I11: FY26 deck sl.35
A12: FY2023-24 | B12: 4631 | C12: 0.0163 | F12: =B12-N(E12) -> 4631 | G12: =B12/AUM!G12 -> 0.016024388 | H12: =B12/B11-1 -> 0.45172414 | I12: FY24 deck sl.14, 38
A13: FY2024-25 | B13: 7966 | C13: 0.0217 | E13: 359 | F13: =B13-N(E13) -> 7607 | G13: =B13/AUM!G13 -> 0.021320101 | H13: =B13/B12-1 -> 0.72014684 | I13: FY26 deck sl.21, 35
A14: FY2025-26 | B14: 10282 | C14: 0.0227 | E14: 1548 | F14: =B14-N(E14) -> 8734 | G14: =B14/AUM!G14 -> 0.022192101 | H14: =B14/B13-1 -> 0.29073563 | I14: FY26 deck sl.21-23, 35
A16: One-time items: FY20 ₹900 cr COVID-19 contingency; FY25 ₹359 cr additional ECL (Q4); FY26 ₹1,406 cr accelerated ECL (Q3) + ₹142 cr overlay (Q4).
A17: FY21–FY24 overlay movements (e.g., ₹1,060 cr overlay held Mar-22; ₹533 cr released in FY24) are noted in Risk_Notes — fill 'One-time' only if you want to adjust those years too.
A18: FY21 write-offs include an accelerated charge-off of ~₹4,193 cr under an advanced write-off policy (FY21 AR p.13). Write-offs FY23–FY26: ECL movement table, Note on Loans, each annual report (optional).

Sheet Capital
A1: Capital adequacy and leverage
A2: CRAR / Tier 1 / Tier 2 are STANDALONE (regulatory). Leverage = total assets ÷ equity, consolidated, as reported by the company.
A4: Financial year | B4: CRAR % | C4: Tier 1 % | D4: Tier 2 % (calc) | E4: Leverage (x, reported) | F4: Total assets | G4: Shareholders' equity | H4: Borrowings (debt + deposits + sub-debt) | I4: Debt / Equity (x) | J4: Assets / Equity (x, calc) | K4: Source
A5: FY2016-17 | B5: 0.203 | C5: 0.146 | D5: =B5-C5 -> 0.057 | E5: 6.6 | I5: =IF(OR(H5="",G5=""),"",H5/G5) | J5: =IF(OR(F5="",G5=""),"",F5/G5) | K5: FY26 deck sl.35, 51
A6: FY2017-18 | B6: 0.2471 | C6: 0.1968 | D6: =B6-C6 -> 0.0503 | E6: 5.4 | I6: =IF(OR(H6="",G6=""),"",H6/G6) | J6: =IF(OR(F6="",G6=""),"",F6/G6) | K6: Q4FY18 deck p.11; FY26 deck sl.51
A7: FY2018-19 | B7: 0.2066 | C7: 0.1627 | D7: =B7-C7 -> 0.0439 | E7: 6.3 | F7: 124233 | G7: 19697 | H7: 101588 | I7: =IF(OR(H7="",G7=""),"",H7/G7) -> 5.1575367 | J7: =IF(OR(F7="",G7=""),"",F7/G7) -> 6.3072041 | K7: FY20 AR p.28, 224-225
A8: FY2019-20 | B8: 0.2501 | C8: 0.2127 | D8: =B8-C8 -> 0.0374 | E8: 5.1 | F8: 164391 | G8: 32328 | H8: 129806 | I8: =IF(OR(H8="",G8=""),"",H8/G8) -> 4.0152809 | J8: =IF(OR(F8="",G8=""),"",F8/G8) -> 5.0850965 | K8: FY20 AR p.11, 27, 224-225
A9: FY2020-21 | B9: 0.2831 | C9: 0.2511 | D9: =B9-C9 -> 0.032 | E9: 4.7 | I9: =IF(OR(H9="",G9=""),"",H9/G9) | J9: =IF(OR(F9="",G9=""),"",F9/G9) | K9: FY21 AR p.13, 21
A10: FY2021-22 | B10: 0.2722 | C10: 0.2475 | D10: =B10-C10 -> 0.0247 | E10: 4.9 | I10: =IF(OR(H10="",G10=""),"",H10/G10) | J10: =IF(OR(F10="",G10=""),"",F10/G10) | K10: FY22 AR p.19, 28
A11: FY2022-23 | B11: 0.2497 | C11: 0.232 | D11: =B11-C11 -> 0.0177 | E11: 5.1 | I11: =IF(OR(H11="",G11=""),"",H11/G11) | J11: =IF(OR(F11="",G11=""),"",F11/G11) | K11: FY23 AR highlights; FY26 deck sl.51
A12: FY2023-24 | B12: 0.2252 | C12: 0.2151 | D12: =B12-C12 -> 0.0101 | E12: 4.9 | I12: =IF(OR(H12="",G12=""),"",H12/G12) | J12: =IF(OR(F12="",G12=""),"",F12/G12) | K12: FY24 deck sl.8
A13: FY2024-25 | B13: 0.219 | C13: 0.211 | D13: =B13-C13 -> 0.008 | E13: 4.7 | I13: =IF(OR(H13="",G13=""),"",H13/G13) | J13: =IF(OR(F13="",G13=""),"",F13/G13) | K13: FY26 deck sl.35, 51
A14: FY2025-26 | B14: 0.2155 | C14: 0.2067 | D14: =B14-C14 -> 0.0088 | E14: 4.8 | I14: =IF(OR(H14="",G14=""),"",H14/G14) | J14: =IF(OR(F14="",G14=""),"",F14/G14) | K14: FY26 deck sl.8, 35
A16: Missing (yellow): total assets, equity and borrowings FY21–FY26 → consolidated balance sheet in each annual report (borrowings = debt securities + other borrowings + deposits + subordinated debt).
A17: Until filled, use the reported leverage ratio as your leverage variable — it is available for all years.

Sheet Profitability
A1: Profitability (₹ crore)
A2: From the company's consolidated multi-year snapshot. Net total income (NTI) = total income − interest expense. FY26 ROA/ROE are after one-time items (before: 4.6% / 19.2%).
A4: Financial year | B4: Total income | C4: Interest expenses | D4: Net total income (NTI) | E4: Net interest income (NII) | F4: Operating expenses | G4: Loan losses & provisions | H4: Profit before tax | I4: Profit after tax | J4: ROA % (reported) | K4: ROE % (reported) | L4: Cost of funds % | M4: Opex / NTI (calc) | N4: Loan losses / NTI (calc) | O4: Pre-provision op. profit (calc) | P4: PAT growth % | Q4: Source
A5: FY2016-17 | B5: 9989 | C5: 3803 | D5: 6186 | F5: 2564 | G5: =Credit_Losses!B5 -> 804 | H5: 2818 | I5: 1837 | J5: 0.037 | K5: 0.216 | L5: 0.09 | M5: =F5/D5 -> 0.41448432 | N5: =G5/D5 -> 0.1299709 | O5: =D5-F5 -> 3622 | Q5: FY26 deck sl.35, 52
A6: FY2017-18 | B6: 12757 | C6: 4614 | D6: 8143 | F6: 3270 | G6: =Credit_Losses!B6 -> 1030 | H6: 3843 | I6: 2496 | J6: 0.037 | K6: 0.201 | L6: 0.0824 | M6: =F6/D6 -> 0.4015719 | N6: =G6/D6 -> 0.12648901 | O6: =D6-F6 -> 4873 | P6: =I6/I5-1 -> 0.35873707 | Q6: FY26 deck sl.35, 52
A7: FY2018-19 | B7: 18500 | C7: 6623 | D7: 11877 | F7: 4197 | G7: =Credit_Losses!B7 -> 1501 | H7: 6179 | I7: 3995 | J7: 0.042 | K7: 0.2248 | L7: 0.0827 | M7: =F7/D7 -> 0.35337206 | N7: =G7/D7 -> 0.12637872 | O7: =D7-F7 -> 7680 | P7: =I7/I6-1 -> 0.6005609 | Q7: FY20 AR p.28; FY26 deck sl.35
A8: FY2019-20 | B8: 26386 | C8: 9473 | D8: 16913 | F8: 5662 | G8: =Credit_Losses!B8 -> 3929 | H8: 7322 | I8: 5264 | J8: 0.0415 | K8: 0.2024 | L8: 0.0839 | M8: =F8/D8 -> 0.33477207 | N8: =G8/D8 -> 0.23230651 | O8: =D8-F8 -> 11251 | P8: =I8/I7-1 -> 0.31764706 | Q8: FY20 AR p.28; FY26 deck sl.35
A9: FY2020-21 | B9: 26683 | C9: 9414 | D9: 17269 | F9: 5308 | G9: =Credit_Losses!B9 -> 5969 | H9: 5992 | I9: 4420 | J9: 0.0307 | K9: 0.1277 | L9: 0.0784 | M9: =F9/D9 -> 0.30737159 | N9: =G9/D9 -> 0.34564827 | O9: =D9-F9 -> 11961 | P9: =I9/I8-1 -> -0.16033435 | Q9: FY21 AR p.20-21; FY26 deck sl.35
A10: FY2021-22 | B10: 31648 | C10: 9754 | D10: 21894 | F10: 7587 | G10: =Credit_Losses!B10 -> 4803 | H10: 9504 | I10: 7028 | J10: 0.0416 | K10: 0.1743 | L10: 0.0681 | M10: =F10/D10 -> 0.3465333 | N10: =G10/D10 -> 0.21937517 | O10: =D10-F10 -> 14307 | P10: =I10/I9-1 -> 0.59004525 | Q10: FY22 AR p.28; FY26 deck sl.35
A11: FY2022-23 | B11: 41418 | C11: 12560 | D11: 28858 | E11: 22989 | F11: 10142 | G11: =Credit_Losses!B11 -> 3190 | H11: 15528 | I11: 11508 | J11: 0.053 | K11: 0.2346 | L11: 0.0704 | M11: =F11/D11 -> 0.35144501 | N11: =G11/D11 -> 0.11054127 | O11: =D11-F11 -> 18716 | P11: =I11/I10-1 -> 0.6374502 | Q11: FY24 deck sl.14, 38
A12: FY2023-24 | B12: 54983 | C12: 18725 | D12: 36258 | E12: 29582 | F12: 12325 | G12: =Credit_Losses!B12 -> 4631 | H12: 19310 | I12: 14451 | J12: 0.0508 | K12: 0.2205 | L12: 0.0774 | M12: =F12/D12 -> 0.33992498 | N12: =G12/D12 -> 0.12772354 | O12: =D12-F12 -> 23933 | P12: =I12/I11-1 -> 0.25573514 | Q12: FY24 deck sl.14, 38
A13: FY2024-25 | B13: 69725 | C13: 24771 | D13: 44954 | E13: 36394 | F13: 14926 | G13: =Credit_Losses!B13 -> 7966 | H13: 22080 | I13: 16779 | J13: 0.046 | K13: 0.192 | L13: 0.0797 | M13: =F13/D13 -> 0.3320283 | N13: =G13/D13 -> 0.17720336 | O13: =D13-F13 -> 30028 | P13: =I13/I12-1 -> 0.16109612 | Q13: FY26 deck sl.35, 44
A14: FY2025-26 | B14: 82789 | C14: 28666 | D14: 54123 | E14: 44110 | F14: 17776 | G14: =Credit_Losses!B14 -> 10282 | H14: 25817 | I14: 19332 | J14: 0.043 | K14: 0.181 | L14: 0.0754 | M14: =F14/D14 -> 0.32843708 | N14: =G14/D14 -> 0.18997469 | O14: =D14-F14 -> 36347 | P14: =I14/I13-1 -> 0.15215448 | Q14: FY26 deck sl.35, 44
A16: NII FY20–FY22: consolidated P&L in each annual report (interest income − finance costs). Cost of funds from FY26 deck sl.52 (FY26: sl.22).

Sheet Liquidity
A1: Liquidity and funding (₹ crore)
A2: Buffer, deposits and borrowing mix are consolidated; LCR and ALM gaps are Bajaj Finance standalone (regulatory). ALM gap = cumulative inflows − outflows as % of outflows (positive = surplus; RBI limits: −10% up to 14 days, −20% up to 1 month).
A4: Financial year | B4: Liquidity buffer | C4: Liquidity coverage ratio (LCR) | D4: Deposits book | E4: Consolidated borrowings | F4: Mix: Deposits | G4: Mix: Bank loans | H4: Mix: NCDs | I4: Mix: Sub-debt | J4: Mix: Short-term (CP etc.) | K4: Mix: ECB | L4: ALM gap up to 1 month | M4: ALM gap up to 1 year | N4: Cost of funds | O4: Buffer / borrowings | P4: Buffer / AUM | Q4: Mix total check | R4: Source
A5: FY2016-17 | F5: 0.08 | G5: 0.35 | H5: 0.4 | I5: 0.07 | J5: 0.1 | K5: 0 | L5: 1.19 | M5: 0.5 | N5: =Profitability!L5 -> 0.09 | O5: =IF(OR(B5="",E5=""),"",B5/E5) | P5: =IF(OR(B5=""),"",B5/AUM!B5) | Q5: =SUM(F5:K5) -> 1 | R5: FY26 deck sl.55-56
A6: FY2017-18 | F6: 0.12 | G6: 0.25 | H6: 0.45 | I6: 0.06 | J6: 0.12 | K6: 0 | L6: 1.2 | M6: 0.96 | N6: =Profitability!L6 -> 0.0824 | O6: =IF(OR(B6="",E6=""),"",B6/E6) | P6: =IF(OR(B6=""),"",B6/AUM!B6) | Q6: =SUM(F6:K6) -> 1 | R6: FY26 deck sl.55-56
A7: FY2018-19 | D7: 13193 | E7: 101588 | F7: 0.13 | G7: 0.34 | H7: 0.36 | I7: 0.04 | J7: 0.13 | K7: 0 | L7: 0.51 | M7: 0.57 | N7: =Profitability!L7 -> 0.0827 | O7: =IF(OR(B7="",E7=""),"",B7/E7) | P7: =IF(OR(B7=""),"",B7/AUM!B7) | Q7: =SUM(F7:K7) -> 1 | R7: FY20 AR p.184 (deposits), p.224 (borrowings); FY26 deck sl.55-56
A8: FY2019-20 | B8: 15725 | D8: 21427 | E8: 129806 | F8: 0.17 | G8: 0.36 | H8: 0.36 | I8: 0.03 | J8: 0.05 | K8: 0.03 | L8: 2.2 | M8: 0.54 | N8: =Profitability!L8 -> 0.0839 | O8: =IF(OR(B8="",E8=""),"",B8/E8) -> 0.12114232 | P8: =IF(OR(B8=""),"",B8/AUM!B8) -> 0.10686157 | Q8: =SUM(F8:K8) -> 1 | R8: FY20 AR p.64, 294; FY26 deck sl.55-56
A9: FY2020-21 | B9: 16485 | C9: 2.7 | D9: 25803 | E9: 131645 | F9: 0.2 | G9: 0.31 | H9: 0.35 | I9: 0.03 | J9: 0.07 | K9: 0.04 | L9: 2.16 | M9: 0.8 | N9: =Profitability!L9 -> 0.0784 | O9: =IF(OR(B9="",E9=""),"",B9/E9) -> 0.12522314 | P9: =IF(OR(B9=""),"",B9/AUM!B9) -> 0.10778243 | Q9: =SUM(F9:K9) -> 1 | R9: FY21 AR p.13, 30, 310; Q4 FY21 update; FY26 deck
A10: FY2021-22 | B10: 10110 | C10: 1.34 | D10: 30800 | F10: 0.19 | G10: 0.28 | H10: 0.4 | I10: 0.02 | J10: 0.08 | K10: 0.03 | L10: 0.31 | M10: 0.32 | N10: =Profitability!L10 -> 0.0681 | O10: =IF(OR(B10="",E10=""),"",B10/E10) | P10: =IF(OR(B10=""),"",B10/AUM!B10) -> 0.051202318 | Q10: =SUM(F10:K10) -> 1 | R10: Q4FY22 deck sl.5-6, 38; FY26 deck
A11: FY2022-23 | B11: 11852 | D11: 44666 | F11: 0.21 | G11: 0.33 | H11: 0.34 | I11: 0.02 | J11: 0.09 | K11: 0.01 | L11: 0.93 | M11: 0.31 | N11: =Profitability!L11 -> 0.0704 | O11: =IF(OR(B11="",E11=""),"",B11/E11) | P11: =IF(OR(B11=""),"",B11/AUM!B11) -> 0.047910291 | Q11: =SUM(F11:K11) -> 1 | R11: 5paisa (Q4 FY23 results); FY26 deck
A12: FY2023-24 | B12: 15668 | C12: 2.6 | D12: 60151 | F12: 0.21 | G12: 0.3 | H12: 0.32 | I12: 0.01 | J12: 0.14 | K12: 0.02 | L12: 0.59 | M12: 0.43 | N12: =Profitability!L12 -> 0.0774 | O12: =IF(OR(B12="",E12=""),"",B12/E12) | P12: =IF(OR(B12=""),"",B12/AUM!B12) -> 0.047390469 | Q12: =SUM(F12:K12) -> 1 | R12: FY24 deck sl.6, 45; FY26 deck
A13: FY2024-25 | B13: =ROUND(2156*71400/8207,0) -> 18757 | C13: 2.88 | D13: 71400 | F13: 0.2 | G13: 0.28 | H13: 0.35 | I13: 0.01 | J13: 0.12 | K13: 0.04 | L13: 0.56 | M13: 0.57 | N13: =Profitability!L13 -> 0.0797 | O13: =IF(OR(B13="",E13=""),"",B13/E13) | P13: =IF(OR(B13=""),"",B13/AUM!B13) -> 0.045017412 | Q13: =SUM(F13:K13) -> 1 | R13: Q4FY25 deck sl.7, 34, 52; BS (Q4 FY25 update)
A14: FY2025-26 | B14: 15020 | C14: 2.28 | D14: 68533 | F14: 0.16 | G14: 0.3 | H14: 0.37 | I14: 0.01 | J14: 0.11 | K14: 0.05 | L14: 0.36 | M14: 0.49 | N14: =Profitability!L14 -> 0.0754 | O14: =IF(OR(B14="",E14=""),"",B14/E14) | P14: =IF(OR(B14=""),"",B14/AUM!B14) -> 0.029452424 | Q14: =SUM(F14:K14) -> 1 | R14: FY26 deck sl.6, 53, 55-56
A16: LCR: Q4 daily average for FY24–FY26; 31-March point value for FY21 (270%) and FY22 (134%). LCR rules started Dec-2020 (grey before). RBI minimum rose from 50% (2020) to 100% (Dec-2024).
A17: FY25 liquidity buffer is an ESTIMATE: the deck gives US$2,156 MM; converted at the deck's implied rate (₹71,400 cr deposits = US$8,207 MM).
A18: Borrowing mix and ALM gaps for FY17–FY26 read from the FY26 deck charts (sl.55-56); they match the year-end tables in the FY24/FY26 decks.
A19: Missing (yellow): buffer FY17–FY19, deposits FY17–FY18, LCR FY23, consolidated borrowings FY22–FY26 (consolidated balance sheet in each annual report).

Sheet Risk_Notes
A1: Risk management and key credit events (paraphrased)
A3: FY | B3: Theme | C3: What happened | D3: Why it matters | E3: Source
A4: All years | B4: Risk appetite | C4: Long-term guidance: GNPA <1.4%, NNPA <0.5%, ROA 4.3–4.7%, ROE 19–21%. | D4: Benchmark for whether asset quality stayed within stated appetite. | E4: FY26 deck sl.32
A5: FY2016-17 | B5: NPA norm tightening | C5: RBI moved NBFC NPA recognition to 4 months overdue (from 5); GNPA 1.68%, NNPA 0.44%, PCR 74%. | D5: Start of the regulatory tightening path. | E5: Q4FY18 deck p.11; FY26 deck sl.35
A6: FY2017-18 | B6: NPA norm tightening | C6: NPA recognition moved to 3 months overdue; a 0.40% general provision on standard assets (0.50% for LAP/LRD/developer finance) under IGAAP. AUM grew 40% (IGAAP). | D6: Comparability break in NPA ratios. | E6: Q4FY18 deck p.11, 33
A7: FY2018-19 | B7: Ind AS / ECL adoption | C7: Moved to Ind AS expected-credit-loss provisioning; Stage 3 coverage settled at ~60% (from 70–75% under IGAAP). AUM grew 41%. | D7: Explains PCR step-down; start of stage-wise data. | E7: Q3FY19 deck sl.45-46; FY26 deck sl.35
A8: FY2018-19 | B8: Liquidity stress | C8: Default by a systemically important NBFC in Sept 2018 tightened funding for the sector; BFL kept a long-dated borrowing mix. | D8: Funding-side risk context for NBFCs. | E8: FY20 AR p.10, 12
A9: FY2019-20 | B9: Risk framework | C9: Dedicated credit-risk units per business; underwriting, risk-containment and fraud-control units; 'acquire and cross-sell' since existing customers carry lower risk. | D9: Evidence of underwriting policy. | E9: FY20 AR p.18
A10: FY2019-20 | B10: COVID-19 provisioning | C10: ₹900 cr contingency provision after moratorium and delayed-payment trends in April 2020; total management overlay ₹921 cr. | D10: Explains credit cost jump 1.55% → 3.10%. | E10: FY20 AR p.11, 302
A11: FY2019-20 | B11: Growth control | C11: Lowered AUM growth across all four quarters; re-pivoted mix to lower-risk mortgages. | D11: Risk-led growth management. | E11: FY20 AR p.18
A12: FY2020-21 | B12: COVID shock | C12: AUM growth fell to 4%; impairment rose 52% to ₹5,969 cr; credit cost peaked at 4.14%; ROE fell to 12.8%. | D12: Peak of the credit cycle in the dataset. | E12: FY21 AR p.13, 21
A13: FY2020-21 | B13: Write-off policy | C13: Advanced its write-off policy and took an accelerated charge-off of ~₹4,193 cr using existing provisions; management overlay ₹840 cr at Mar-21. | D13: Explains record write-offs (₹5,554 cr). | E13: FY21 AR p.13
A14: FY2020-21 | B14: Collections | C14: Offered moratorium and resolution plans; set up 10 dedicated collection branches; trained ~6,700 recovery agents; strengthened digital overdue payment channels. | D14: Collection-practice evidence. | E14: FY21 AR p.13
... A28: FY2025-26 | B28: Outlook | C28: FY27 credit cost guided at 1.45–1.60% of avg AUF. | D28: For recommendations. | E28: FY26 deck sl.28

Sheet Sources
A1: Sources and remaining gaps
A3: Short name | B3: Document | C3: Link
A4: FY20 AR | B4: Bajaj Finance 33rd Annual Report 2019-20 (printed page numbers) | C4: https://www.bseindia.com/bseplus/AnnualReport/500034/5000340320.pdf
A5: FY18 deck | B5: Q4 FY18 Investor Presentation, 17 May 2018 (IGAAP; FY17–FY18 AUM, NPA, CRAR) | C5: https://bsmedia.business-standard.com/_media/bs/data/announcements/bse/17052018/8486d97e-ab2b-4c8c-98be-b5929ca60a3c.pdf
A6: Q3FY19 deck | B6: Q3 FY19 Investor Presentation (Ind AS restated Mar-2018 NPA, stages, PCR) | C6: https://bseindia.com/xml-data/corpfiling/AttachHis/11bc5b36-29ed-4a89-a6eb-41bd0aba5a43.pdf
A7: FY18 / FY19 AR | B7: 31st / 32nd Annual Reports (BSE) — for deeper checks | C7: https://www.bseindia.com/bseplus/AnnualReport/500034/5000340318.pdf
A8: FY21 AR | B8: 34th Annual Report 2020-21 (printed pages: p.13 highlights, p.20 AUM table, p.21 key ratios, p.25 risk, p.259-261 Note 9 Loans) | C8: https://cms-assets.bajajfinserv.in/is/content/bajajfinance/bajaj-finance-limited-annual-report-fy2021-newpdf?scl=1&fmt=pdf
A9: FY22 AR | B9: 35th Annual Report 2021-22 — MD&A (p.19 highlights, p.26 AUM table, p.28 key ratios, p.28-33 risk) | C9: https://www.bajajfinserv.in/finance-digital-annual-report-fy22/finance-digital-annual-report-assets/pdf/BFL-Management-Discussion-and-Analysis.pdf
