Workbook

Sheet README
A1: Mahindra & Mahindra Financial Services Ltd (Mahindra Finance) — CONSOLIDATED credit-risk dataset, FY2016-17 to FY2025-26
A3: Basis | B3: CONSOLIDATED (group: Mahindra Finance + Mahindra Rural Housing Finance + Mahindra Insurance Brokers + other subsidiaries/JV), ₹ crore, years ending 31 March — same basis as the Bajaj Finance consolidated file.
A4: Sources | B4: Every blue number is typed from the consolidated financial statements in Mahindra Finance's annual reports (printed page numbers in the last column of each sheet). Nothing is estimated. FY2024-25 and FY2025-26 annual reports are still needed — those rows are yellow.
A5: AUM measure | B5: AUM = gross loans in the consolidated 'Loans' note (before impairment allowance). Net loans = balance-sheet loans after allowance.
A6: NPA terms | B6: GNPA ≡ Gross Stage 3; NNPA = Stage 3 − Stage 3 ECL. Mahindra does not print consolidated GNPA/NNPA %; they are calculated here (formulas).
A7: Stages | B7: Mahindra prints stage tables per portfolio (retail incl. finance lease, housing, SME incl. bills, trade advances). Stage figures here are their sum; the Stage_ECL sheet checks them against the Loans note.
A8: Accounting breaks | B8: FY2016-17 is previous Indian GAAP (no stages/ECL – grey). FY2017-18 uses the Ind AS restated comparatives in the FY2018-19 annual report.
A9: Standalone-only items | B9: CRAR / Tier 1 (regulatory ratios), LCR, liquidity buffer, ALM buckets and vehicle-wise product mix are reported only for the standalone company — CRAR/Tier 1 are shown from the standalone file; the rest are in Mahindra_Finance_10yr_Dataset.xlsx (standalone).
A10: Colour code | B10: Blue = figure from an annual report · Black = formula · Green = linked from another sheet · Yellow = not yet available · Grey = not applicable.
A12: Sheet | B12: What it holds
A13: Master_Dataset | B13: One row per year, every key variable, linked from the topic sheets — same layout as the Bajaj master.
A14: Formulas_Guide | B14: Every formula: plain-English version, purpose, actual Excel formula.
A15: AUM | B15: Gross and net loans, growth, average AUM.
... A24: Sources | B24: Each annual report, link, and pages used; list of gaps.

Sheet Master_Dataset
A1: Master dataset — Mahindra Finance (CONSOLIDATED), one row per year
A2: All cells link to the topic sheets (green) — edit numbers there, not here. Column order follows the Bajaj master.
A4: Financial year | B4: Company | C4: AUM (₹ cr) | D4: AUM growth % | E4: GNPA % | F4: NNPA % | G4: Gross NPA ₹ | H4: Net NPA ₹ | I4: PCR % | J4: Stage 2 % of loans | K4: Stage 3 % of loans | L4: Total ECL (₹ cr) | M4: Loan losses (₹ cr) | N4: Credit cost % (calc, avg AUM) | O4: Write-offs (₹ cr) | P4: CRAR % (standalone) | Q4: Tier 1 % (standalone) | R4: Leverage (x) | S4: Debt / Equity (x) | T4: NTI (₹ cr) | U4: PAT (₹ cr, owners) | V4: ROA % | W4: ROE % | X4: Opex / NTI | Y4: Loan losses / NTI | Z4: Liquid assets (₹ cr) | AA4: Deposits % of borrowings | AB4: Cost of funds proxy
A5: FY2016-17 | B5: Mahindra Finance (consolidated) | C5: =IF(AUM!B5="","",AUM!B5) -> 47994.47 | D5: =IF(AUM!D5="","",AUM!D5) | E5: =IF(Asset_Quality!E5="","",Asset_Quality!E5) -> 0.083275011 | F5: =IF(Asset_Quality!F5="","",Asset_Quality!F5) -> 0.042176453 | G5: =IF(Asset_Quality!B5="","",Asset_Quality!B5) -> 3996.74 | H5: =IF(Asset_Quality!D5="","",Asset_Quality!D5) -> 1937.38 | I5: =IF(Asset_Quality!G5="","",Asset_Quality!G5) -> 0.51525994 | J5: =IF(Stage_ECL!K5="","",Stage_ECL!K5) | K5: =IF(Stage_ECL!L5="","",Stage_ECL!L5) | L5: =IF(Stage_ECL!H5="","",Stage_ECL!H5) | M5: =IF(Credit_Losses!B5="","",Credit_Losses!B5) -> 1389.55 | N5: =IF(Credit_Losses!E5="","",Credit_Losses!E5) | O5: =IF(Credit_Losses!C5="","",Credit_Losses!C5) -> 863.26 | P5: =IF(Capital!B5="","",Capital!B5) -> 0.172 | Q5: =IF(Capital!C5="","",Capital!C5) -> 0.128 | R5: =IF(Capital!O5="","",Capital!O5) -> 7.5647128 | S5: =IF(Capital!N5="","",Capital!N5) -> 5.7806347 | T5: =IF(Profitability!I5="","",Profitability!I5) -> 4014.48 | U5: =IF(Profitability!N5="","",Profitability!N5) -> 511.64 | V5: =IF(Profitability!O5="","",Profitability!O5) | W5: =IF(Profitability!P5="","",Profitability!P5) | X5: =IF(Profitability!Q5="","",Profitability!Q5) -> 0.44518094 | Y5: =IF(Profitability!R5="","",Profitability!R5) -> 0.34613449 | Z5: =IF(Liquidity!D5="","",Liquidity!D5) -> 603.88 | AA5: =IF(Liquidity!H5="","",Liquidity!H5) -> 0.10447097 | AB5: =IF(Liquidity!L5="","",Liquidity!L5)
A6: FY2017-18 | B6: Mahindra Finance (consolidated) | C6: =IF(AUM!B6="","",AUM!B6) -> 57832.53 | D6: =IF(AUM!D6="","",AUM!D6) -> 0.2049832 | E6: =IF(Asset_Quality!E6="","",Asset_Quality!E6) -> 0.10178839 | F6: =IF(Asset_Quality!F6="","",Asset_Quality!F6) -> 0.072108221 | G6: =IF(Asset_Quality!B6="","",Asset_Quality!B6) -> 5886.68 | H6: =IF(Asset_Quality!D6="","",Asset_Quality!D6) -> 4036.81 | I6: =IF(Asset_Quality!G6="","",Asset_Quality!G6) -> 0.31424674 | J6: =IF(Stage_ECL!K6="","",Stage_ECL!K6) -> 0.10768881 | K6: =IF(Stage_ECL!L6="","",Stage_ECL!L6) -> 0.10179307 | L6: =IF(Stage_ECL!H6="","",Stage_ECL!H6) -> 3282.8 | M6: =IF(Credit_Losses!B6="","",Credit_Losses!B6) -> 676.86 | N6: =IF(Credit_Losses!E6="","",Credit_Losses!E6) -> 0.012791821 | O6: =IF(Credit_Losses!C6="","",Credit_Losses!C6) -> 1041.6 | P6: =IF(Capital!B6="","",Capital!B6) -> 0.22 | Q6: =IF(Capital!C6="","",Capital!C6) -> 0.161 | R6: =IF(Capital!O6="","",Capital!O6) -> 5.8729553 | S6: =IF(Capital!N6="","",Capital!N6) -> 4.49857 | T6: =IF(Profitability!I6="","",Profitability!I6) -> 4475.99 | U6: =IF(Profitability!N6="","",Profitability!N6) -> 1185.19 | V6: =IF(Profitability!O6="","",Profitability!O6) -> 0.021692985 | W6: =IF(Profitability!P6="","",Profitability!P6) -> 0.14096684 | X6: =IF(Profitability!Q6="","",Profitability!Q6) -> 0.43007469 | Y6: =IF(Profitability!R6="","",Profitability!R6) -> 0.15122018 | Z6: =IF(Liquidity!D6="","",Liquidity!D6) -> 477.91 | AA6: =IF(Liquidity!H6="","",Liquidity!H6) -> 0.067844214 | AB6: =IF(Liquidity!L6="","",Liquidity!L6) -> 0.080100283
A7: FY2018-19 | B7: Mahindra Finance (consolidated) | C7: =IF(AUM!B7="","",AUM!B7) -> 71161.53 | D7: =IF(AUM!D7="","",AUM!D7) -> 0.23047582 | E7: =IF(Asset_Quality!E7="","",Asset_Quality!E7) -> 0.071925941 | F7: =IF(Asset_Quality!F7="","",Asset_Quality!F7) -> 0.059075913 | G7: =IF(Asset_Quality!B7="","",Asset_Quality!B7) -> 5118.36 | H7: =IF(Asset_Quality!D7="","",Asset_Quality!D7) -> 4146.52 | I7: =IF(Asset_Quality!G7="","",Asset_Quality!G7) -> 0.18987332 | J7: =IF(Stage_ECL!K7="","",Stage_ECL!K7) -> 0.096169218 | K7: =IF(Stage_ECL!L7="","",Stage_ECL!L7) -> 0.071927083 | L7: =IF(Stage_ECL!H7="","",Stage_ECL!H7) -> 2222.53 | M7: =IF(Credit_Losses!B7="","",Credit_Losses!B7) -> 717.11 | N7: =IF(Credit_Losses!E7="","",Credit_Losses!E7) -> 0.011118496 | O7: =IF(Credit_Losses!C7="","",Credit_Losses!C7) -> 1801.71 | P7: =IF(Capital!B7="","",Capital!B7) -> 0.203 | Q7: =IF(Capital!C7="","",Capital!C7) -> 0.155 | R7: =IF(Capital!O7="","",Capital!O7) -> 6.5720003 | S7: =IF(Capital!N7="","",Capital!N7) -> 5.1818872 | T7: =IF(Profitability!I7="","",Profitability!I7) -> 5998.57 | U7: =IF(Profitability!N7="","",Profitability!N7) -> 1827.3 | V7: =IF(Profitability!O7="","",Profitability!O7) -> 0.02801492 | W7: =IF(Profitability!P7="","",Profitability!P7) -> 0.17300684 | X7: =IF(Profitability!Q7="","",Profitability!Q7) -> 0.41470384 | Y7: =IF(Profitability!R7="","",Profitability!R7) -> 0.11954683 | Z7: =IF(Liquidity!D7="","",Liquidity!D7) -> 994.03 | AA7: =IF(Liquidity!H7="","",Liquidity!H7) -> 0.095761477 | AB7: =IF(Liquidity!L7="","",Liquidity!L7) -> 0.085410449
A8: FY2019-20 | B8: Mahindra Finance (consolidated) | C8: =IF(AUM!B8="","",AUM!B8) -> 76520.33 | D8: =IF(AUM!D8="","",AUM!D8) -> 0.075304733 | E8: =IF(Asset_Quality!E8="","",Asset_Quality!E8) -> 0.091723467 | F8: =IF(Asset_Quality!F8="","",Asset_Quality!F8) -> 0.064968635 | G8: =IF(Asset_Quality!B8="","",Asset_Quality!B8) -> 7018.71 | H8: =IF(Asset_Quality!D8="","",Asset_Quality!D8) -> 4829.17 | I8: =IF(Asset_Quality!G8="","",Asset_Quality!G8) -> 0.31195761 | J8: =IF(Stage_ECL!K8="","",Stage_ECL!K8) -> 0.10585475 | K8: =IF(Stage_ECL!L8="","",Stage_ECL!L8) -> 0.091724942 | L8: =IF(Stage_ECL!H8="","",Stage_ECL!H8) -> 3656.54 | M8: =IF(Credit_Losses!B8="","",Credit_Losses!B8) -> 2318.98 | N8: =IF(Credit_Losses!E8="","",Credit_Losses!E8) -> 0.031405076 | O8: =IF(Credit_Losses!C8="","",Credit_Losses!C8) -> 889.38 | P8: =IF(Capital!B8="","",Capital!B8) -> 0.196 | Q8: =IF(Capital!C8="","",Capital!C8) -> 0.154 | R8: =IF(Capital!O8="","",Capital!O8) -> 6.78288 | S8: =IF(Capital!N8="","",Capital!N8) -> 5.4429042 | T8: =IF(Profitability!I8="","",Profitability!I8) -> 6605.9 | U8: =IF(Profitability!N8="","",Profitability!N8) -> 1075.15 | V8: =IF(Profitability!O8="","",Profitability!O8) -> 0.013887959 | W8: =IF(Profitability!P8="","",Profitability!P8) -> 0.092533701 | X8: =IF(Profitability!Q8="","",Profitability!Q8) -> 0.41338652 | Y8: =IF(Profitability!R8="","",Profitability!R8) -> 0.35104679 | Z8: =IF(Liquidity!D8="","",Liquidity!D8) -> 1531.6 | AA8: =IF(Liquidity!H8="","",Liquidity!H8) -> 0.13379282 | AB8: =IF(Liquidity!L8="","",Liquidity!L8) -> 0.086639977
A9: FY2020-21 | B9: Mahindra Finance (consolidated) | C9: =IF(AUM!B9="","",AUM!B9) -> 72239.57 | D9: =IF(AUM!D9="","",AUM!D9) -> -0.05594278 | E9: =IF(Asset_Quality!E9="","",Asset_Quality!E9) -> 0.093911135 | F9: =IF(Asset_Quality!F9="","",Asset_Quality!F9) -> 0.046065572 | G9: =IF(Asset_Quality!B9="","",Asset_Quality!B9) -> 6784.1 | H9: =IF(Asset_Quality!D9="","",Asset_Quality!D9) -> 3160.85 | I9: =IF(Asset_Quality!G9="","",Asset_Quality!G9) -> 0.53407969 | J9: =IF(Stage_ECL!K9="","",Stage_ECL!K9) -> 0.14116997 | K9: =IF(Stage_ECL!L9="","",Stage_ECL!L9) -> 0.093912682 | L9: =IF(Stage_ECL!H9="","",Stage_ECL!H9) -> 5163.85 | M9: =IF(Credit_Losses!B9="","",Credit_Losses!B9) -> 3998.74 | N9: =IF(Credit_Losses!E9="","",Credit_Losses!E9) -> 0.053760993 | O9: =IF(Credit_Losses!C9="","",Credit_Losses!C9) -> 2486.85 | P9: =IF(Capital!B9="","",Capital!B9) -> 0.26 | Q9: =IF(Capital!C9="","",Capital!C9) -> 0.222 | R9: =IF(Capital!O9="","",Capital!O9) -> 5.3920117 | S9: =IF(Capital!N9="","",Capital!N9) -> 4.1007129 | T9: =IF(Profitability!I9="","",Profitability!I9) -> 6862.93 | U9: =IF(Profitability!N9="","",Profitability!N9) -> 773.21 | V9: =IF(Profitability!O9="","",Profitability!O9) -> 0.0093226998 | W9: =IF(Profitability!P9="","",Profitability!P9) -> 0.055736146 | X9: =IF(Profitability!Q9="","",Profitability!Q9) -> 0.32029031 | Y9: =IF(Profitability!R9="","",Profitability!R9) -> 0.58265784 | Z9: =IF(Liquidity!D9="","",Liquidity!D9) -> 3982.52 | AA9: =IF(Liquidity!H9="","",Liquidity!H9) -> 0.14387133 | AB9: =IF(Liquidity!L9="","",Liquidity!L9) -> 0.081195736
A10: FY2021-22 | B10: Mahindra Finance (consolidated) | C10: =IF(AUM!B10="","",AUM!B10) -> 72741.07 | D10: =IF(AUM!D10="","",AUM!D10) -> 0.0069421786 | E10: =IF(Asset_Quality!E10="","",Asset_Quality!E10) -> 0.080412345 | F10: =IF(Asset_Quality!F10="","",Asset_Quality!F10) -> 0.039187849 | G10: =IF(Asset_Quality!B10="","",Asset_Quality!B10) -> 5849.28 | H10: =IF(Asset_Quality!D10="","",Asset_Quality!D10) -> 2728.26 | I10: =IF(Asset_Quality!G10="","",Asset_Quality!G10) -> 0.53357336 | J10: =IF(Stage_ECL!K10="","",Stage_ECL!K10) -> 0.1554567 | K10: =IF(Stage_ECL!L10="","",Stage_ECL!L10) -> 0.080412533 | L10: =IF(Stage_ECL!H10="","",Stage_ECL!H10) -> 5081.38 | M10: =IF(Credit_Losses!B10="","",Credit_Losses!B10) -> 2690.38 | N10: =IF(Credit_Losses!E10="","",Credit_Losses!E10) -> 0.037113645 | O10: =IF(Credit_Losses!C10="","",Credit_Losses!C10) -> 2777.3 | P10: =IF(Capital!B10="","",Capital!B10) -> 0.278 | Q10: =IF(Capital!C10="","",Capital!C10) -> 0.243 | R10: =IF(Capital!O10="","",Capital!O10) -> 4.9189917 | S10: =IF(Capital!N10="","",Capital!N10) -> 3.6463475 | T10: =IF(Profitability!I10="","",Profitability!I10) -> 6983.14 | U10: =IF(Profitability!N10="","",Profitability!N10) -> 1136.87 | V10: =IF(Profitability!O10="","",Profitability!O10) -> 0.013580573 | W10: =IF(Profitability!P10="","",Profitability!P10) -> 0.069591475 | X10: =IF(Profitability!Q10="","",Profitability!Q10) -> 0.40224455 | Y10: =IF(Profitability!R10="","",Profitability!R10) -> 0.38526795 | Z10: =IF(Liquidity!D10="","",Liquidity!D10) -> 4827.61 | AA10: =IF(Liquidity!H10="","",Liquidity!H10) -> 0.13337909 | AB10: =IF(Liquidity!L10="","",Liquidity!L10) -> 0.069440993
A11: FY2022-23 | B11: Mahindra Finance (consolidated) | C11: =IF(AUM!B11="","",AUM!B11) -> 90105.36 | D11: =IF(AUM!D11="","",AUM!D11) -> 0.2387137 | E11: =IF(Asset_Quality!E11="","",Asset_Quality!E11) -> 0.049963842 | F11: =IF(Asset_Quality!F11="","",Asset_Quality!F11) -> 0.02387724 | G11: =IF(Asset_Quality!B11="","",Asset_Quality!B11) -> 4502.01 | H11: =IF(Asset_Quality!D11="","",Asset_Quality!D11) -> 2093.97 | I11: =IF(Asset_Quality!G11="","",Asset_Quality!G11) -> 0.53488109 | J11: =IF(Stage_ECL!K11="","",Stage_ECL!K11) -> 0.067266225 | K11: =IF(Stage_ECL!L11="","",Stage_ECL!L11) -> 0.049963903 | L11: =IF(Stage_ECL!H11="","",Stage_ECL!H11) -> 3649.29 | M11: =IF(Credit_Losses!B11="","",Credit_Losses!B11) -> 1182.59 | N11: =IF(Credit_Losses!E11="","",Credit_Losses!E11) -> 0.01452399 | O11: =IF(Credit_Losses!C11="","",Credit_Losses!C11) -> 2606.74 | P11: =IF(Capital!B11="","",Capital!B11) -> 0.225 | Q11: =IF(Capital!C11="","",Capital!C11) -> 0.199 | R11: =IF(Capital!O11="","",Capital!O11) -> 5.6190737 | S11: =IF(Capital!N11="","",Capital!N11) -> 4.3541332 | T11: =IF(Profitability!I11="","",Profitability!I11) -> 7738.1 | U11: =IF(Profitability!N11="","",Profitability!N11) -> 2072.4 | V11: =IF(Profitability!O11="","",Profitability!O11) -> 0.021929827 | W11: =IF(Profitability!P11="","",Profitability!P11) -> 0.1168985 | X11: =IF(Profitability!Q11="","",Profitability!Q11) -> 0.48319484 | Y11: =IF(Profitability!R11="","",Profitability!R11) -> 0.15282692 | Z11: =IF(Liquidity!D11="","",Liquidity!D11) -> 4066.91 | AA11: =IF(Liquidity!H11="","",Liquidity!H11) -> 0.067037167 | AB11: =IF(Liquidity!L11="","",Liquidity!L11) -> 0.070973895
A12: FY2023-24 | B12: Mahindra Finance (consolidated) | C12: =IF(AUM!B12="","",AUM!B12) -> 110025.82 | D12: =IF(AUM!D12="","",AUM!D12) -> 0.22107963 | E12: =IF(Asset_Quality!E12="","",Asset_Quality!E12) -> 0.037756592 | F12: =IF(Asset_Quality!F12="","",Asset_Quality!F12) -> 0.016064383 | G12: =IF(Asset_Quality!B12="","",Asset_Quality!B12) -> 4154.2 | H12: =IF(Asset_Quality!D12="","",Asset_Quality!D12) -> 1728.53 | I12: =IF(Asset_Quality!G12="","",Asset_Quality!G12) -> 0.58390785 | J12: =IF(Stage_ECL!K12="","",Stage_ECL!K12) -> 0.052638773 | K12: =IF(Stage_ECL!L12="","",Stage_ECL!L12) -> 0.037756619 | L12: =IF(Stage_ECL!H12="","",Stage_ECL!H12) -> 3681.86 | M12: =IF(Credit_Losses!B12="","",Credit_Losses!B12) -> 1955.75 | N12: =IF(Credit_Losses!E12="","",Credit_Losses!E12) -> 0.019544681 | O12: =IF(Credit_Losses!C12="","",Credit_Losses!C12) -> 1931.3 | P12: =IF(Capital!B12="","",Capital!B12) -> 0.189 | Q12: =IF(Capital!C12="","",Capital!C12) -> 0.164 | R12: =IF(Capital!O12="","",Capital!O12) -> 6.1935748 | S12: =IF(Capital!N12="","",Capital!N12) -> 4.9221436 | T12: =IF(Profitability!I12="","",Profitability!I12) -> 9011.12 | U12: =IF(Profitability!N12="","",Profitability!N12) -> 1932.69 | V12: =IF(Profitability!O12="","",Profitability!O12) -> 0.016984661 | W12: =IF(Profitability!P12="","",Profitability!P12) -> 0.10041685 | X12: =IF(Profitability!Q12="","",Profitability!Q12) -> 0.50196868 | Y12: =IF(Profitability!R12="","",Profitability!R12) -> 0.21703739 | Z12: =IF(Liquidity!D12="","",Liquidity!D12) -> 3455.01 | AA12: =IF(Liquidity!H12="","",Liquidity!H12) -> 0.072973896 | AB12: =IF(Liquidity!L12="","",Liquidity!L12) -> 0.077432984
A13: FY2024-25 | B13: Mahindra Finance (consolidated) | C13: =IF(AUM!B13="","",AUM!B13) | D13: =IF(AUM!D13="","",AUM!D13) | E13: =IF(Asset_Quality!E13="","",Asset_Quality!E13) | F13: =IF(Asset_Quality!F13="","",Asset_Quality!F13) | G13: =IF(Asset_Quality!B13="","",Asset_Quality!B13) | H13: =IF(Asset_Quality!D13="","",Asset_Quality!D13) | I13: =IF(Asset_Quality!G13="","",Asset_Quality!G13) | J13: =IF(Stage_ECL!K13="","",Stage_ECL!K13) | K13: =IF(Stage_ECL!L13="","",Stage_ECL!L13) | L13: =IF(Stage_ECL!H13="","",Stage_ECL!H13) | M13: =IF(Credit_Losses!B13="","",Credit_Losses!B13) | N13: =IF(Credit_Losses!E13="","",Credit_Losses!E13) | O13: =IF(Credit_Losses!C13="","",Credit_Losses!C13) | P13: =IF(Capital!B13="","",Capital!B13) -> 0.183 | Q13: =IF(Capital!C13="","",Capital!C13) -> 0.152 | R13: =IF(Capital!O13="","",Capital!O13) | S13: =IF(Capital!N13="","",Capital!N13) | T13: =IF(Profitability!I13="","",Profitability!I13) | U13: =IF(Profitability!N13="","",Profitability!N13) | V13: =IF(Profitability!O13="","",Profitability!O13) | W13: =IF(Profitability!P13="","",Profitability!P13) | X13: =IF(Profitability!Q13="","",Profitability!Q13) | Y13: =IF(Profitability!R13="","",Profitability!R13) | Z13: =IF(Liquidity!D13="","",Liquidity!D13) | AA13: =IF(Liquidity!H13="","",Liquidity!H13) | AB13: =IF(Liquidity!L13="","",Liquidity!L13)
A14: FY2025-26 | B14: Mahindra Finance (consolidated) | C14: =IF(AUM!B14="","",AUM!B14) | D14: =IF(AUM!D14="","",AUM!D14) | E14: =IF(Asset_Quality!E14="","",Asset_Quality!E14) | F14: =IF(Asset_Quality!F14="","",Asset_Quality!F14) | G14: =IF(Asset_Quality!B14="","",Asset_Quality!B14) | H14: =IF(Asset_Quality!D14="","",Asset_Quality!D14) | I14: =IF(Asset_Quality!G14="","",Asset_Quality!G14) | J14: =IF(Stage_ECL!K14="","",Stage_ECL!K14) | K14: =IF(Stage_ECL!L14="","",Stage_ECL!L14) | L14: =IF(Stage_ECL!H14="","",Stage_ECL!H14) | M14: =IF(Credit_Losses!B14="","",Credit_Losses!B14) | N14: =IF(Credit_Losses!E14="","",Credit_Losses!E14) | O14: =IF(Credit_Losses!C14="","",Credit_Losses!C14) | P14: =IF(Capital!B14="","",Capital!B14) -> 0.188 | Q14: =IF(Capital!C14="","",Capital!C14) -> 0.167 | R14: =IF(Capital!O14="","",Capital!O14) | S14: =IF(Capital!N14="","",Capital!N14) | T14: =IF(Profitability!I14="","",Profitability!I14) | U14: =IF(Profitability!N14="","",Profitability!N14) | V14: =IF(Profitability!O14="","",Profitability!O14) | W14: =IF(Profitability!P14="","",Profitability!P14) | X14: =IF(Profitability!Q14="","",Profitability!Q14) | Y14: =IF(Profitability!R14="","",Profitability!R14) | Z14: =IF(Liquidity!D14="","",Liquidity!D14) | AA14: =IF(Liquidity!H14="","",Liquidity!H14) | AB14: =IF(Liquidity!L14="","",Liquidity!L14)
A16: Blank = not yet available (FY25–FY26 annual reports pending) or not applicable (FY17 IGAAP has no stages). CRAR/Tier 1 are standalone (regulatory) and so appear for FY25–FY26.

Sheet Formulas_Guide
A1: Formulas guide — every calculated column, what it does and why
A2: t = current year, t−1 = previous year. 'Excel formula' shows the formula in the FY2023-24 row (other years use the same formula on their own row).
A4: # | B4: Sheet | C4: Column | D4: Plain-English formula | E4: Why it is there | F4: Excel formula (FY2023-24 row) | G4: Cell
A5: 1 | B5: AUM | C5: AUM growth % | D5: AUM(t) ÷ AUM(t−1) − 1 | E5: Loan-book growth. | F5: =IF(OR(B12="",B11=""),"",B12/B11-1) | G5: AUM!D12
A6: 2 | B6: AUM | C6: AUM added | D6: AUM(t) − AUM(t−1) | E6: Absolute expansion. | F6: =IF(OR(B12="",B11=""),"",B12-B11) | G6: AUM!E12
A7: 3 | B7: AUM | C7: Average AUM | D7: (AUM(t) + AUM(t−1)) ÷ 2 | E7: Denominator for credit cost. | F7: =IF(OR(B12="",B11=""),"",AVERAGE(B12,B11)) | G7: AUM!F12
A8: 4 | B8: Stage_ECL | C8: Total loans (S1+S2+S3) | D8: Stage 1 + 2 + 3 | E8: Check against AUM. | F8: =IF(COUNT(B12:D12)<3,"",SUM(B12:D12)) | G8: Stage_ECL!I12
A9: 5 | B9: Stage_ECL | C9: Total ECL (S1+S2+S3) | D9: ECL 1 + 2 + 3 | E9: Check against Loans-note ECL. | F9: =IF(COUNT(E12:G12)<3,"",SUM(E12:G12)) | G9: Stage_ECL!J12
A10: 6 | B10: Stage_ECL | C10: Stage 2 % | D10: Stage 2 ÷ total | E10: Early-warning stress. | F10: =IF(OR(I12=""),"",C12/I12) | G10: Stage_ECL!K12
A11: 7 | B11: Stage_ECL | C11: Stage 3 % | D11: Stage 3 ÷ total | E11: Credit-impaired share. | F11: =IF(OR(I12=""),"",D12/I12) | G11: Stage_ECL!L12
A12: 8 | B12: Stage_ECL | C12: ECL cover Stage 1+2 | D12: (ECL1+ECL2) ÷ (S1+S2) | E12: Provisioning on performing loans. | F12: =IF(OR(I12="",J12=""),"",(E12+F12)/(B12+C12)) | G12: Stage_ECL!M12
A13: 9 | B13: Stage_ECL | C13: ECL cover Stage 3 | D13: ECL3 ÷ S3 | E13: Same as PCR. | F13: =IF(COUNT(D12,G12)<2,"",G12/D12) | G13: Stage_ECL!N12
A14: 10 | B14: Stage_ECL | C14: Total ECL / loans | D14: Total ECL ÷ total loans | E14: Overall cushion. | F14: =IF(OR(I12="",J12=""),"",J12/I12) | G14: Stage_ECL!O12
A15: 11 | B15: Stage_ECL | C15: Gap: AUM − stage total | D15: AUM − (S1+S2+S3) | E15: Reconciliation check. | F15: =IF(OR(I12="",AUM!B12=""),"",AUM!B12-I12) | G15: Stage_ECL!P12
A16: 12 | B16: Stage_ECL | C16: Gap: Loans-note ECL − stage ECL | D16: Reported ECL − summed ECL | E16: Reconciliation check. | F16: =IF(COUNT(H12)<1,"",IF(J12="","",H12-J12)) | G16: Stage_ECL!Q12
... A48: 44 | B48: Master_Dataset | C48: Every column | D48: =IF(source cell="","",source cell) | E48: One table for analysis; blanks stay blank. | F48: =IF(AUM!B12="","",AUM!B12) | G48: Master_Dataset!C12
A49: 45 | B49: All sheets | C49: Blank / completeness guards | D49: IF(OR(input=""),"",…) and IF(COUNT(range)<n,"",…) | E49: No errors or false zeros when inputs are missing.

Sheet AUM
A1: Assets under management — consolidated gross and net loans (₹ crore)
A2: AUM = gross loans (Loans note, before impairment allowance). Net loans = balance-sheet 'Loans'.
A4: Financial year | B4: AUM — gross loans | C4: Net loans (balance sheet) | D4: AUM growth % | E4: AUM added | F4: Average AUM | G4: Source (document · slide/page)
A5: FY2016-17 | B5: 47994.47 | G5: AR 2016-17 pp.229, 233 (loans against assets incl. overdue, IGAAP)
A6: FY2017-18 | B6: 57832.53 | C6: 54549.73 | D6: =IF(OR(B6="",B5=""),"",B6/B5-1) -> 0.2049832 | E6: =IF(OR(B6="",B5=""),"",B6-B5) -> 9838.06 | F6: =IF(OR(B6="",B5=""),"",AVERAGE(B6,B5)) -> 52913.5 | G6: AR 2018-19 (FY18 Ind AS comparatives) note 7 p.268; p.250
A7: FY2018-19 | B7: 71161.53 | C7: 68939 | D7: =IF(OR(B7="",B6=""),"",B7/B6-1) -> 0.23047582 | E7: =IF(OR(B7="",B6=""),"",B7-B6) -> 13329 | F7: =IF(OR(B7="",B6=""),"",AVERAGE(B7,B6)) -> 64497.03 | G7: AR 2018-19 note 7 p.268; p.250
A8: FY2019-20 | B8: 76520.33 | C8: 72863.78 | D8: =IF(OR(B8="",B7=""),"",B8/B7-1) -> 0.075304733 | E8: =IF(OR(B8="",B7=""),"",B8-B7) -> 5358.8 | F8: =IF(OR(B8="",B7=""),"",AVERAGE(B8,B7)) -> 73840.93 | G8: AR 2019-20 note 7 p.295; p.276
A9: FY2020-21 | B9: 72239.57 | C9: 67075.72 | D9: =IF(OR(B9="",B8=""),"",B9/B8-1) -> -0.05594278 | E9: =IF(OR(B9="",B8=""),"",B9-B8) -> -4280.76 | F9: =IF(OR(B9="",B8=""),"",AVERAGE(B9,B8)) -> 74379.95 | G9: IAR 2020-21 note 7 p.353; p.330
A10: FY2021-22 | B10: 72741.07 | C10: 67659.69 | D10: =IF(OR(B10="",B9=""),"",B10/B9-1) -> 0.0069421786 | E10: =IF(OR(B10="",B9=""),"",B10-B9) -> 501.5 | F10: =IF(OR(B10="",B9=""),"",AVERAGE(B10,B9)) -> 72490.32 | G10: IR 2021-22 note 7 p.347; p.326
A11: FY2022-23 | B11: 90105.36 | C11: 86456.07 | D11: =IF(OR(B11="",B10=""),"",B11/B10-1) -> 0.2387137 | E11: =IF(OR(B11="",B10=""),"",B11-B10) -> 17364.29 | F11: =IF(OR(B11="",B10=""),"",AVERAGE(B11,B10)) -> 81423.215 | G11: IR 2022-23 note 7 p.437; p.412
A12: FY2023-24 | B12: 110025.82 | C12: 106343.96 | D12: =IF(OR(B12="",B11=""),"",B12/B11-1) -> 0.22107963 | E12: =IF(OR(B12="",B11=""),"",B12-B11) -> 19920.46 | F12: =IF(OR(B12="",B11=""),"",AVERAGE(B12,B11)) -> 100065.59 | G12: IR 2023-24 note 6 p.420; p.396
A13: FY2024-25 | D13: =IF(OR(B13="",B12=""),"",B13/B12-1) | E13: =IF(OR(B13="",B12=""),"",B13-B12) | F13: =IF(OR(B13="",B12=""),"",AVERAGE(B13,B12)) | G13: Pending – AR 2024-25
A14: FY2025-26 | D14: =IF(OR(B14="",B13=""),"",B14/B13-1) | E14: =IF(OR(B14="",B13=""),"",B14-B13) | F14: =IF(OR(B14="",B13=""),"",AVERAGE(B14,B13)) | G14: Pending – IAR 2025-26
A16: FY17 = loans against assets (secured + doubtful), IGAAP; net loans not reported on the same basis (yellow). FY17→FY18 growth crosses the IGAAP→Ind AS break.
A17: FY18 IGAAP loans against assets were ₹57,832 cr gross as well (AR 2017-18 notes 15, 20, pp.246, 249) — the two bases are close for this line.

Sheet Segment_AUM
A1: Product mix — consolidated gross loans by product (₹ crore and % share)
A2: From the consolidated Loans note. Vehicle-wise split (UV, cars, tractors, CV, pre-owned) is disclosed only for the standalone company — see the standalone file.
A4: Financial year | B4: Retail loans | C4: Housing finance | D4: SME financing | E4: Bills of exchange | F4: Trade advances | G4: Finance lease | H4: Inter-corporate deposits & other | I4: Total (calc) | J4: Check vs AUM | K4: Retail % | L4: Housing % | M4: SME + bills % | N4: Trade advances % | O4: Finance lease % | P4: Source (document · slide/page)
A5: FY2016-17 | I5: =IF(COUNT(B5:H5)<7,"",SUM(B5:H5)) | J5: =IF(OR(I5="",AUM!B5=""),"",I5-AUM!B5) | K5: =IF(I5="","",B5/I5) | L5: =IF(I5="","",C5/I5) | M5: =IF(I5="","",(D5+E5)/I5) | N5: =IF(I5="","",F5/I5) | O5: =IF(I5="","",G5/I5) | P5: AR 2016-17 – product split not extracted (IGAAP notes show loans against assets / trade advances)
A6: FY2017-18 | B6: 48169.6 | C6: 6312.17 | D6: 1360.49 | E6: 550.32 | F6: 1437.27 | G6: 0 | H6: 2.67 | I6: =IF(COUNT(B6:H6)<7,"",SUM(B6:H6)) -> 57832.52 | J6: =IF(OR(I6="",AUM!B6=""),"",I6-AUM!B6) -> -0.01 | K6: =IF(I6="","",B6/I6) -> 0.83291546 | L6: =IF(I6="","",C6/I6) -> 0.10914568 | M6: =IF(I6="","",(D6+E6)/I6) -> 0.033040407 | N6: =IF(I6="","",F6/I6) -> 0.02485228 | O6: =IF(I6="","",G6/I6) -> 0 | P6: AR 2018-19 (FY18 Ind AS comparatives) note 7 p.268
A7: FY2018-19 | B7: 58741.47 | C7: 8048.75 | D7: 1880.53 | E7: 615.35 | F7: 1874.31 | G7: 0 | H7: 1.12 | I7: =IF(COUNT(B7:H7)<7,"",SUM(B7:H7)) -> 71161.53 | J7: =IF(OR(I7="",AUM!B7=""),"",I7-AUM!B7) -> 0 | K7: =IF(I7="","",B7/I7) -> 0.82546665 | L7: =IF(I7="","",C7/I7) -> 0.11310535 | M7: =IF(I7="","",(D7+E7)/I7) -> 0.035073445 | N7: =IF(I7="","",F7/I7) -> 0.02633881 | O7: =IF(I7="","",G7/I7) -> 0 | P7: AR 2018-19 note 7 p.268
A8: FY2019-20 | B8: 64439.78 | C8: 8443.89 | D8: 1864.41 | E8: 531.66 | F8: 1239.35 | G8: 0 | H8: 1.23 | I8: =IF(COUNT(B8:H8)<7,"",SUM(B8:H8)) -> 76520.32 | J8: =IF(OR(I8="",AUM!B8=""),"",I8-AUM!B8) -> -0.01 | K8: =IF(I8="","",B8/I8) -> 0.84212638 | L8: =IF(I8="","",C8/I8) -> 0.11034834 | M8: =IF(I8="","",(D8+E8)/I8) -> 0.031312859 | N8: =IF(I8="","",F8/I8) -> 0.016196352 | O8: =IF(I8="","",G8/I8) -> 0 | P8: AR 2019-20 note 7 p.295
A9: FY2020-21 | B9: 61638.86 | C9: 7646.71 | D9: 1014.73 | E9: 743.1 | F9: 1194.98 | G9: 0 | H9: 1.19 | I9: =IF(COUNT(B9:H9)<7,"",SUM(B9:H9)) -> 72239.57 | J9: =IF(OR(I9="",AUM!B9=""),"",I9-AUM!B9) -> 0 | K9: =IF(I9="","",B9/I9) -> 0.85325619 | L9: =IF(I9="","",C9/I9) -> 0.1058521 | M9: =IF(I9="","",(D9+E9)/I9) -> 0.02433334 | N9: =IF(I9="","",F9/I9) -> 0.016541904 | O9: =IF(I9="","",G9/I9) -> 0 | P9: IAR 2020-21 note 7 p.353
A10: FY2021-22 | B10: 61066.67 | C10: 7603.45 | D10: 1196.15 | E10: 944.33 | F10: 1807.42 | G10: 122.88 | H10: 0.17 | I10: =IF(COUNT(B10:H10)<7,"",SUM(B10:H10)) -> 72741.07 | J10: =IF(OR(I10="",AUM!B10=""),"",I10-AUM!B10) -> 0 | K10: =IF(I10="","",B10/I10) -> 0.83950745 | L10: =IF(I10="","",C10/I10) -> 0.10452761 | M10: =IF(I10="","",(D10+E10)/I10) -> 0.029426018 | N10: =IF(I10="","",F10/I10) -> 0.024847311 | O10: =IF(I10="","",G10/I10) -> 0.0016892795 | P10: IR 2021-22 note 7 p.347
A11: FY2022-23 | B11: 75687.27 | C11: 7199.93 | D11: 3481.07 | E11: 975.61 | F11: 2540.42 | G11: 220.95 | H11: 0.11 | I11: =IF(COUNT(B11:H11)<7,"",SUM(B11:H11)) -> 90105.36 | J11: =IF(OR(I11="",AUM!B11=""),"",I11-AUM!B11) -> 0 | K11: =IF(I11="","",B11/I11) -> 0.83998632 | L11: =IF(I11="","",C11/I11) -> 0.079905679 | M11: =IF(I11="","",(D11+E11)/I11) -> 0.049460765 | N11: =IF(I11="","",F11/I11) -> 0.028193883 | O11: =IF(I11="","",G11/I11) -> 0.0024521294 | P11: IR 2022-23 note 7 p.437
A12: FY2023-24 | B12: 94410.63 | C12: 7209.08 | D12: 3757.67 | E12: 1054.74 | F12: 2879.1 | G12: 714.52 | H12: 0.08 | I12: =IF(COUNT(B12:H12)<7,"",SUM(B12:H12)) -> 110025.82 | J12: =IF(OR(I12="",AUM!B12=""),"",I12-AUM!B12) -> 0 | K12: =IF(I12="","",B12/I12) -> 0.85807704 | L12: =IF(I12="","",C12/I12) -> 0.065521711 | M12: =IF(I12="","",(D12+E12)/I12) -> 0.043738915 | N12: =IF(I12="","",F12/I12) -> 0.026167494 | O12: =IF(I12="","",G12/I12) -> 0.006494112 | P12: IR 2023-24 note 6 p.420
A13: FY2024-25 | I13: =IF(COUNT(B13:H13)<7,"",SUM(B13:H13)) | J13: =IF(OR(I13="",AUM!B13=""),"",I13-AUM!B13) | K13: =IF(I13="","",B13/I13) | L13: =IF(I13="","",C13/I13) | M13: =IF(I13="","",(D13+E13)/I13) | N13: =IF(I13="","",F13/I13) | O13: =IF(I13="","",G13/I13) | P13: Pending – AR 2024-25
A14: FY2025-26 | I14: =IF(COUNT(B14:H14)<7,"",SUM(B14:H14)) | J14: =IF(OR(I14="",AUM!B14=""),"",I14-AUM!B14) | K14: =IF(I14="","",B14/I14) | L14: =IF(I14="","",C14/I14) | M14: =IF(I14="","",(D14+E14)/I14) | N14: =IF(I14="","",F14/I14) | O14: =IF(I14="","",G14/I14) | P14: Pending – IAR 2025-26
A16: FY18 'other' includes retained interest under assignment (₹1.47 cr). Finance lease shown separately from FY22 (earlier inside other categories). Retail = vehicle and other retail loans of the parent.
A17: Housing finance = Mahindra Rural Housing Finance (subsidiary). Product definitions are the company's and may shift between years.
A20: Risk tier by product (analyst view)
A21: Product | B21: Secured / Unsecured | C21: Risk tier | D21: Why
A22: Retail loans | B22: Secured (vehicle) | C22: Medium–High | D22: Rural/semi-urban vehicle, tractor and pre-owned loans; farm-income dependence
A23: Housing finance | B23: Secured (property) | C23: High | D23: Rural affordable housing; highest Stage 3 ratio of the group's portfolios
A24: SME financing + bills | B24: Mixed | C24: High | D24: Small-business cash flows; bill discounting short tenor
A25: Trade advances | B25: Mostly unsecured | C25: Low–Medium | D25: Short-term dealer/channel finance (~90 days)
A26: Finance lease | B26: Secured (asset) | C26: Medium | D26: Vehicle leasing

Sheet Asset_Quality
A1: Asset quality — GNPA and NNPA (consolidated)
A2: GNPA ₹ = Stage 3 loans (FY17: IGAAP non-performing loans). NNPA ₹ = GNPA − Stage 3 ECL (FY17: − NPA provisions). Ratios calculated — Mahindra does not print consolidated %.
A4: Financial year | B4: Gross NPA ₹ (Stage 3) | C4: Stage 3 provision / NPA provision ₹ | D4: Net NPA ₹ (calc) | E4: GNPA % (calc) | F4: NNPA % (calc) | G4: PCR % (calc) | H4: Change in GNPA (pp) | I4: Source (document · slide/page)
A5: FY2016-17 | B5: 3996.74 | C5: 2059.36 | D5: =IF(OR(B5="",C5=""),"",B5-C5) -> 1937.38 | E5: =IF(OR(B5="",AUM!B5=""),"",B5/AUM!B5) -> 0.083275011 | F5: =IF(OR(D5="",AUM!B5=""),"",D5/(AUM!B5-C5)) -> 0.042176453 | G5: =IF(OR(B5="",C5=""),"",C5/B5) -> 0.51525994 | I5: AR 2016-17 NPA amounts noted under loan tables pp.229, 233; NPA provisions pp.219, 221
A6: FY2017-18 | B6: =Stage_ECL!D6 -> 5886.68 | C6: =Stage_ECL!G6 -> 1849.87 | D6: =IF(OR(B6="",C6=""),"",B6-C6) -> 4036.81 | E6: =IF(OR(B6="",AUM!B6=""),"",B6/AUM!B6) -> 0.10178839 | F6: =IF(OR(D6="",AUM!B6=""),"",D6/(AUM!B6-C6)) -> 0.072108221 | G6: =IF(OR(B6="",C6=""),"",C6/B6) -> 0.31424674 | H6: =IF(OR(E6="",E5=""),"",E6-E5) -> 0.018513377 | I6: Linked from Stage_ECL (AR 2018-19 (FY18 Ind AS comparatives) pp.310-311)
A7: FY2018-19 | B7: =Stage_ECL!D7 -> 5118.36 | C7: =Stage_ECL!G7 -> 971.84 | D7: =IF(OR(B7="",C7=""),"",B7-C7) -> 4146.52 | E7: =IF(OR(B7="",AUM!B7=""),"",B7/AUM!B7) -> 0.071925941 | F7: =IF(OR(D7="",AUM!B7=""),"",D7/(AUM!B7-C7)) -> 0.059075913 | G7: =IF(OR(B7="",C7=""),"",C7/B7) -> 0.18987332 | H7: =IF(OR(E7="",E6=""),"",E7-E6) -> -0.029862447 | I7: Linked from Stage_ECL (AR 2018-19 pp.310-311)
A8: FY2019-20 | B8: =Stage_ECL!D8 -> 7018.71 | C8: =Stage_ECL!G8 -> 2189.54 | D8: =IF(OR(B8="",C8=""),"",B8-C8) -> 4829.17 | E8: =IF(OR(B8="",AUM!B8=""),"",B8/AUM!B8) -> 0.091723467 | F8: =IF(OR(D8="",AUM!B8=""),"",D8/(AUM!B8-C8)) -> 0.064968635 | G8: =IF(OR(B8="",C8=""),"",C8/B8) -> 0.31195761 | H8: =IF(OR(E8="",E7=""),"",E8-E7) -> 0.019797527 | I8: Linked from Stage_ECL (AR 2019-20 pp.330-331)
A9: FY2020-21 | B9: =Stage_ECL!D9 -> 6784.1 | C9: =Stage_ECL!G9 -> 3623.25 | D9: =IF(OR(B9="",C9=""),"",B9-C9) -> 3160.85 | E9: =IF(OR(B9="",AUM!B9=""),"",B9/AUM!B9) -> 0.093911135 | F9: =IF(OR(D9="",AUM!B9=""),"",D9/(AUM!B9-C9)) -> 0.046065572 | G9: =IF(OR(B9="",C9=""),"",C9/B9) -> 0.53407969 | H9: =IF(OR(E9="",E8=""),"",E9-E8) -> 0.0021876674 | I9: Linked from Stage_ECL (IAR 2020-21 pp.395-396)
A10: FY2021-22 | B10: =Stage_ECL!D10 -> 5849.28 | C10: =Stage_ECL!G10 -> 3121.02 | D10: =IF(OR(B10="",C10=""),"",B10-C10) -> 2728.26 | E10: =IF(OR(B10="",AUM!B10=""),"",B10/AUM!B10) -> 0.080412345 | F10: =IF(OR(D10="",AUM!B10=""),"",D10/(AUM!B10-C10)) -> 0.039187849 | G10: =IF(OR(B10="",C10=""),"",C10/B10) -> 0.53357336 | H10: =IF(OR(E10="",E9=""),"",E10-E9) -> -0.01349879 | I10: Linked from Stage_ECL (IR 2021-22 pp.390-391)
A11: FY2022-23 | B11: =Stage_ECL!D11 -> 4502.01 | C11: =Stage_ECL!G11 -> 2408.04 | D11: =IF(OR(B11="",C11=""),"",B11-C11) -> 2093.97 | E11: =IF(OR(B11="",AUM!B11=""),"",B11/AUM!B11) -> 0.049963842 | F11: =IF(OR(D11="",AUM!B11=""),"",D11/(AUM!B11-C11)) -> 0.02387724 | G11: =IF(OR(B11="",C11=""),"",C11/B11) -> 0.53488109 | H11: =IF(OR(E11="",E10=""),"",E11-E10) -> -0.030448502 | I11: Linked from Stage_ECL (IR 2022-23 pp.483-484)
A12: FY2023-24 | B12: =Stage_ECL!D12 -> 4154.2 | C12: =Stage_ECL!G12 -> 2425.67 | D12: =IF(OR(B12="",C12=""),"",B12-C12) -> 1728.53 | E12: =IF(OR(B12="",AUM!B12=""),"",B12/AUM!B12) -> 0.037756592 | F12: =IF(OR(D12="",AUM!B12=""),"",D12/(AUM!B12-C12)) -> 0.016064383 | G12: =IF(OR(B12="",C12=""),"",C12/B12) -> 0.58390785 | H12: =IF(OR(E12="",E11=""),"",E12-E11) -> -0.01220725 | I12: Linked from Stage_ECL (IR 2023-24 pp.465-466)
A13: FY2024-25 | D13: =IF(OR(B13="",C13=""),"",B13-C13) | E13: =IF(OR(B13="",AUM!B13=""),"",B13/AUM!B13) | F13: =IF(OR(D13="",AUM!B13=""),"",D13/(AUM!B13-C13)) | G13: =IF(OR(B13="",C13=""),"",C13/B13) | H13: =IF(OR(E13="",E12=""),"",E13-E12) | I13: Pending – AR 2024-25
A14: FY2025-26 | D14: =IF(OR(B14="",C14=""),"",B14-C14) | E14: =IF(OR(B14="",AUM!B14=""),"",B14/AUM!B14) | F14: =IF(OR(D14="",AUM!B14=""),"",D14/(AUM!B14-C14)) | G14: =IF(OR(B14="",C14=""),"",C14/B14) | H14: =IF(OR(E14="",E13=""),"",E14-E13) | I14: Pending – IAR 2025-26
A16: FY17 GNPA (₹3,997 cr) is the sum of all non-performing loans under IGAAP; the standalone deck figure (₹4,183 cr) is on a different basis and is not reconciled. FY17→FY18 change crosses the IGAAP→Ind AS break.
A17: NNPA % denominator = gross loans − Stage 3 provision. Consolidated GNPA runs above the standalone figure because the housing subsidiary is included.
A18: IGAAP FY18 for reference (AR 2017-18 notes 15, 20, 7, 11): non-performing loans ₹4,697 cr, NPA provisions ₹2,266 cr.

Sheet Stage_ECL
A1: Stage-wise loans and ECL (₹ crore, consolidated)
A2: Stage 1 = 0-30 dpd, Stage 2 = 31-90 dpd, Stage 3 = >90 dpd / credit-impaired (AR 2018-19 p.308). Sum of retail, housing, SME and trade-advance tables; ECL = gross − carrying amount.
A4: Financial year | B4: Stage 1 loans | C4: Stage 2 loans | D4: Stage 3 loans | E4: ECL Stage 1 | F4: ECL Stage 2 | G4: ECL Stage 3 | H4: Total ECL (Loans note) | I4: Total loans (S1+S2+S3) | J4: Total ECL (S1+S2+S3) | K4: Stage 2 % | L4: Stage 3 % | M4: ECL cover Stage 1+2 | N4: ECL cover Stage 3 | O4: Total ECL / loans | P4: Gap: AUM − stage total | Q4: Gap: Loans-note ECL − stage ECL | R4: Source (document · slide/page)
A5: FY2016-17 | I5: =IF(COUNT(B5:D5)<3,"",SUM(B5:D5)) | J5: =IF(COUNT(E5:G5)<3,"",SUM(E5:G5)) | K5: =IF(OR(I5=""),"",C5/I5) | L5: =IF(OR(I5=""),"",D5/I5) | M5: =IF(OR(I5="",J5=""),"",(E5+F5)/(B5+C5)) | N5: =IF(COUNT(D5,G5)<2,"",G5/D5) | O5: =IF(OR(I5="",J5=""),"",J5/I5) | P5: =IF(OR(I5="",AUM!B5=""),"",AUM!B5-I5) | Q5: =IF(COUNT(H5)<1,"",IF(J5="","",H5-J5)) | R5: AR 2016-17 (IGAAP – no stages)
A6: FY2017-18 | B6: 45715.56 | C6: 6227.63 | D6: 5886.68 | E6: 548.26 | F6: 883.69 | G6: 1849.87 | H6: 3282.8 | I6: =IF(COUNT(B6:D6)<3,"",SUM(B6:D6)) -> 57829.87 | J6: =IF(COUNT(E6:G6)<3,"",SUM(E6:G6)) -> 3281.82 | K6: =IF(OR(I6=""),"",C6/I6) -> 0.10768881 | L6: =IF(OR(I6=""),"",D6/I6) -> 0.10179307 | M6: =IF(OR(I6="",J6=""),"",(E6+F6)/(B6+C6)) -> 0.027567618 | N6: =IF(COUNT(D6,G6)<2,"",G6/D6) -> 0.31424674 | O6: =IF(OR(I6="",J6=""),"",J6/I6) -> 0.056749566 | P6: =IF(OR(I6="",AUM!B6=""),"",AUM!B6-I6) -> 2.66 | Q6: =IF(COUNT(H6)<1,"",IF(J6="","",H6-J6)) -> 0.98 | R6: AR 2018-19 (FY18 Ind AS comparatives) stages pp.310-311; Loans note note 7 p.268
A7: FY2018-19 | B7: 59198.6 | C7: 6843.44 | D7: 5118.36 | E7: 569.71 | F7: 679.96 | G7: 971.84 | H7: 2222.53 | I7: =IF(COUNT(B7:D7)<3,"",SUM(B7:D7)) -> 71160.4 | J7: =IF(COUNT(E7:G7)<3,"",SUM(E7:G7)) -> 2221.51 | K7: =IF(OR(I7=""),"",C7/I7) -> 0.096169218 | L7: =IF(OR(I7=""),"",D7/I7) -> 0.071927083 | M7: =IF(OR(I7="",J7=""),"",(E7+F7)/(B7+C7)) -> 0.018922341 | N7: =IF(COUNT(D7,G7)<2,"",G7/D7) -> 0.18987332 | O7: =IF(OR(I7="",J7=""),"",J7/I7) -> 0.031218346 | P7: =IF(OR(I7="",AUM!B7=""),"",AUM!B7-I7) -> 1.13 | Q7: =IF(COUNT(H7)<1,"",IF(J7="","",H7-J7)) -> 1.02 | R7: AR 2018-19 stages pp.310-311; Loans note note 7 p.268
A8: FY2019-20 | B8: 61400.48 | C8: 8099.91 | D8: 7018.71 | E8: 604.36 | F8: 861.65 | G8: 2189.54 | H8: 3656.54 | I8: =IF(COUNT(B8:D8)<3,"",SUM(B8:D8)) -> 76519.1 | J8: =IF(COUNT(E8:G8)<3,"",SUM(E8:G8)) -> 3655.55 | K8: =IF(OR(I8=""),"",C8/I8) -> 0.10585475 | L8: =IF(OR(I8=""),"",D8/I8) -> 0.091724942 | M8: =IF(OR(I8="",J8=""),"",(E8+F8)/(B8+C8)) -> 0.021093551 | N8: =IF(COUNT(D8,G8)<2,"",G8/D8) -> 0.31195761 | O8: =IF(OR(I8="",J8=""),"",J8/I8) -> 0.04777304 | P8: =IF(OR(I8="",AUM!B8=""),"",AUM!B8-I8) -> 1.23 | Q8: =IF(COUNT(H8)<1,"",IF(J8="","",H8-J8)) -> 0.99 | R8: AR 2019-20 stages pp.330-331; Loans note note 7 p.295
A9: FY2020-21 | B9: 55256.39 | C9: 10197.89 | D9: 6784.1 | E9: 482.01 | F9: 1057.56 | G9: 3623.25 | H9: 5163.85 | I9: =IF(COUNT(B9:D9)<3,"",SUM(B9:D9)) -> 72238.38 | J9: =IF(COUNT(E9:G9)<3,"",SUM(E9:G9)) -> 5162.82 | K9: =IF(OR(I9=""),"",C9/I9) -> 0.14116997 | L9: =IF(OR(I9=""),"",D9/I9) -> 0.093912682 | M9: =IF(OR(I9="",J9=""),"",(E9+F9)/(B9+C9)) -> 0.023521304 | N9: =IF(COUNT(D9,G9)<2,"",G9/D9) -> 0.53407969 | O9: =IF(OR(I9="",J9=""),"",J9/I9) -> 0.071469211 | P9: =IF(OR(I9="",AUM!B9=""),"",AUM!B9-I9) -> 1.19 | Q9: =IF(COUNT(H9)<1,"",IF(J9="","",H9-J9)) -> 1.03 | R9: IAR 2020-21 stages pp.395-396; Loans note note 7 p.353
A10: FY2021-22 | B10: 55583.56 | C10: 11308.06 | D10: 5849.28 | E10: 537.19 | F10: 1416.94 | G10: 3121.02 | H10: 5081.38 | I10: =IF(COUNT(B10:D10)<3,"",SUM(B10:D10)) -> 72740.9 | J10: =IF(COUNT(E10:G10)<3,"",SUM(E10:G10)) -> 5075.15 | K10: =IF(OR(I10=""),"",C10/I10) -> 0.1554567 | L10: =IF(OR(I10=""),"",D10/I10) -> 0.080412533 | M10: =IF(OR(I10="",J10=""),"",(E10+F10)/(B10+C10)) -> 0.029213375 | N10: =IF(COUNT(D10,G10)<2,"",G10/D10) -> 0.53357336 | O10: =IF(OR(I10="",J10=""),"",J10/I10) -> 0.069770239 | P10: =IF(OR(I10="",AUM!B10=""),"",AUM!B10-I10) -> 0.17 | Q10: =IF(COUNT(H10)<1,"",IF(J10="","",H10-J10)) -> 6.23 | R10: IR 2021-22 stages pp.390-391; Loans note note 7 p.347
A11: FY2022-23 | B11: 79542.2 | C11: 6061.04 | D11: 4502.01 | E11: 590.31 | F11: 619.78 | G11: 2408.04 | H11: 3649.29 | I11: =IF(COUNT(B11:D11)<3,"",SUM(B11:D11)) -> 90105.25 | J11: =IF(COUNT(E11:G11)<3,"",SUM(E11:G11)) -> 3618.13 | K11: =IF(OR(I11=""),"",C11/I11) -> 0.067266225 | L11: =IF(OR(I11=""),"",D11/I11) -> 0.049963903 | M11: =IF(OR(I11="",J11=""),"",(E11+F11)/(B11+C11)) -> 0.01413603 | N11: =IF(COUNT(D11,G11)<2,"",G11/D11) -> 0.53488109 | O11: =IF(OR(I11="",J11=""),"",J11/I11) -> 0.040154486 | P11: =IF(OR(I11="",AUM!B11=""),"",AUM!B11-I11) -> 0.11 | Q11: =IF(COUNT(H11)<1,"",IF(J11="","",H11-J11)) -> 31.16 | R11: IR 2022-23 stages pp.483-484; Loans note note 7 p.437
A12: FY2023-24 | B12: 100079.92 | C12: 5791.62 | D12: 4154.2 | E12: 647.05 | F12: 639.77 | G12: 2425.67 | H12: 3681.86 | I12: =IF(COUNT(B12:D12)<3,"",SUM(B12:D12)) -> 110025.74 | J12: =IF(COUNT(E12:G12)<3,"",SUM(E12:G12)) -> 3712.49 | K12: =IF(OR(I12=""),"",C12/I12) -> 0.052638773 | L12: =IF(OR(I12=""),"",D12/I12) -> 0.037756619 | M12: =IF(OR(I12="",J12=""),"",(E12+F12)/(B12+C12)) -> 0.012154541 | N12: =IF(COUNT(D12,G12)<2,"",G12/D12) -> 0.58390785 | O12: =IF(OR(I12="",J12=""),"",J12/I12) -> 0.033742013 | P12: =IF(OR(I12="",AUM!B12=""),"",AUM!B12-I12) -> 0.08 | Q12: =IF(COUNT(H12)<1,"",IF(J12="","",H12-J12)) -> -30.63 | R12: IR 2023-24 stages pp.465-466; Loans note note 6 p.420
A13: FY2024-25 | I13: =IF(COUNT(B13:D13)<3,"",SUM(B13:D13)) | J13: =IF(COUNT(E13:G13)<3,"",SUM(E13:G13)) | K13: =IF(OR(I13=""),"",C13/I13) | L13: =IF(OR(I13=""),"",D13/I13) | M13: =IF(OR(I13="",J13=""),"",(E13+F13)/(B13+C13)) | N13: =IF(COUNT(D13,G13)<2,"",G13/D13) | O13: =IF(OR(I13="",J13=""),"",J13/I13) | P13: =IF(OR(I13="",AUM!B13=""),"",AUM!B13-I13) | Q13: =IF(COUNT(H13)<1,"",IF(J13="","",H13-J13)) | R13: Pending – AR 2024-25
A14: FY2025-26 | I14: =IF(COUNT(B14:D14)<3,"",SUM(B14:D14)) | J14: =IF(COUNT(E14:G14)<3,"",SUM(E14:G14)) | K14: =IF(OR(I14=""),"",C14/I14) | L14: =IF(OR(I14=""),"",D14/I14) | M14: =IF(OR(I14="",J14=""),"",(E14+F14)/(B14+C14)) | N14: =IF(COUNT(D14,G14)<2,"",G14/D14) | O14: =IF(OR(I14="",J14=""),"",J14/I14) | P14: =IF(OR(I14="",AUM!B14=""),"",AUM!B14-I14) | Q14: =IF(COUNT(H14)<1,"",IF(J14="","",H14-J14)) | R14: Pending – IAR 2025-26
A16: Gross gap = small loans outside the stage tables (inter-corporate deposits, other loans; FY18 also retained interest ₹1.47 cr).
A17: ECL gap: ~₹1 cr FY18–FY21 (inter-corporate deposit fully provided); ₹6 cr FY22 and ~₹31 cr FY23–FY24 — shown as reported, not forced.
A18: Trade advances use Ind AS 109 simplified approach (<60 dpd / 61-90 dpd / >90 dpd), mapped to Stage 1/2/3. FY2016-17 is IGAAP: no stages (grey).

Sheet Credit_Losses
A1: Credit losses — impairment, write-offs and credit cost (₹ crore, consolidated)
A2: Loan losses = 'Impairment on financial instruments' (FY17 IGAAP: 'Loan provisions and write offs'). Credit cost = loan losses ÷ average AUM (same as the Bajaj calc column).
A4: Financial year | B4: Loan losses (impairment, P&L) | C4: Bad debts & write-offs | D4: Net provision charge (calc) | E4: Credit cost % (calc, avg AUM) | F4: Write-offs / avg AUM | G4: PPOP (calc) | H4: Loan losses / PPOP | I4: Source (document · slide/page)
A5: FY2016-17 | B5: 1389.55 | C5: 863.26 | D5: =IF(OR(B5="",C5=""),"",B5-C5) -> 526.29 | G5: =IF(Profitability!$K5="","",Profitability!$K5) -> 2227.31 | H5: =IF(OR(B5="",G5=""),"",B5/G5) -> 0.62386915 | I5: AR 2016-17 p.205; note 25 p.235
A6: FY2017-18 | B6: 676.86 | C6: 1041.6 | D6: =IF(OR(B6="",C6=""),"",B6-C6) -> -364.74 | E6: =IF(OR(B6="",AUM!F6=""),"",B6/AUM!F6) -> 0.012791821 | F6: =IF(OR(C6="",AUM!F6=""),"",C6/AUM!F6) -> 0.019684958 | G6: =IF(Profitability!$K6="","",Profitability!$K6) -> 2550.98 | H6: =IF(OR(B6="",G6=""),"",B6/G6) -> 0.26533332 | I6: AR 2018-19 (FY18 Ind AS comparatives) p.251; note 30 p.286
A7: FY2018-19 | B7: 717.11 | C7: 1801.71 | D7: =IF(OR(B7="",C7=""),"",B7-C7) -> -1084.6 | E7: =IF(OR(B7="",AUM!F7=""),"",B7/AUM!F7) -> 0.011118496 | F7: =IF(OR(C7="",AUM!F7=""),"",C7/AUM!F7) -> 0.027934775 | G7: =IF(Profitability!$K7="","",Profitability!$K7) -> 3510.94 | H7: =IF(OR(B7="",G7=""),"",B7/G7) -> 0.20425014 | I7: AR 2018-19 p.251; note 30 p.286
A8: FY2019-20 | B8: 2318.98 | C8: 889.38 | D8: =IF(OR(B8="",C8=""),"",B8-C8) -> 1429.6 | E8: =IF(OR(B8="",AUM!F8=""),"",B8/AUM!F8) -> 0.031405076 | F8: =IF(OR(C8="",AUM!F8=""),"",C8/AUM!F8) -> 0.01204454 | G8: =IF(Profitability!$K8="","",Profitability!$K8) -> 3875.11 | H8: =IF(OR(B8="",G8=""),"",B8/G8) -> 0.59842946 | I8: AR 2019-20 p.277; note 30 p.311
A9: FY2020-21 | B9: 3998.74 | C9: 2486.85 | D9: =IF(OR(B9="",C9=""),"",B9-C9) -> 1511.89 | E9: =IF(OR(B9="",AUM!F9=""),"",B9/AUM!F9) -> 0.053760993 | F9: =IF(OR(C9="",AUM!F9=""),"",C9/AUM!F9) -> 0.033434413 | G9: =IF(Profitability!$K9="","",Profitability!$K9) -> 4664.8 | H9: =IF(OR(B9="",G9=""),"",B9/G9) -> 0.85721574 | I9: IAR 2020-21 p.331; note 30 p.371
A10: FY2021-22 | B10: 2690.38 | C10: 2777.3 | D10: =IF(OR(B10="",C10=""),"",B10-C10) -> -86.92 | E10: =IF(OR(B10="",AUM!F10=""),"",B10/AUM!F10) -> 0.037113645 | F10: =IF(OR(C10="",AUM!F10=""),"",C10/AUM!F10) -> 0.038312702 | G10: =IF(Profitability!$K10="","",Profitability!$K10) -> 4174.21 | H10: =IF(OR(B10="",G10=""),"",B10/G10) -> 0.64452435 | I10: IR 2021-22 p.327; note 30 p.368
A11: FY2022-23 | B11: 1182.59 | C11: 2606.74 | D11: =IF(OR(B11="",C11=""),"",B11-C11) -> -1424.15 | E11: =IF(OR(B11="",AUM!F11=""),"",B11/AUM!F11) -> 0.01452399 | F11: =IF(OR(C11="",AUM!F11=""),"",C11/AUM!F11) -> 0.032014702 | G11: =IF(Profitability!$K11="","",Profitability!$K11) -> 3999.09 | H11: =IF(OR(B11="",G11=""),"",B11/G11) -> 0.29571478 | I11: IR 2022-23 p.413; note 30 p.458
A12: FY2023-24 | B12: 1955.75 | C12: 1931.3 | D12: =IF(OR(B12="",C12=""),"",B12-C12) -> 24.45 | E12: =IF(OR(B12="",AUM!F12=""),"",B12/AUM!F12) -> 0.019544681 | F12: =IF(OR(C12="",AUM!F12=""),"",C12/AUM!F12) -> 0.019300341 | G12: =IF(Profitability!$K12="","",Profitability!$K12) -> 4487.82 | H12: =IF(OR(B12="",G12=""),"",B12/G12) -> 0.43579065 | I12: IR 2023-24 p.397; note 29 p.440
A13: FY2024-25 | D13: =IF(OR(B13="",C13=""),"",B13-C13) | E13: =IF(OR(B13="",AUM!F13=""),"",B13/AUM!F13) | F13: =IF(OR(C13="",AUM!F13=""),"",C13/AUM!F13) | G13: =IF(Profitability!$K13="","",Profitability!$K13) | H13: =IF(OR(B13="",G13=""),"",B13/G13) | I13: Pending – AR 2024-25
A14: FY2025-26 | D14: =IF(OR(B14="",C14=""),"",B14-C14) | E14: =IF(OR(B14="",AUM!F14=""),"",B14/AUM!F14) | F14: =IF(OR(C14="",AUM!F14=""),"",C14/AUM!F14) | G14: =IF(Profitability!$K14="","",Profitability!$K14) | H14: =IF(OR(B14="",G14=""),"",B14/G14) | I14: Pending – IAR 2025-26
A16: FY17 (IGAAP) loan losses ₹1,390 cr = write-offs ₹863 cr + NPA provision ₹499 cr + standard-asset provision ₹27 cr (note 25). FY18 IGAAP loan provisions & write-offs were ₹1,327 cr (AR 2017-18 note 27 p.252); Ind AS ₹677 cr used.
A17: Negative net provision = provisions released (write-offs exceeded impairment), e.g. FY19, FY22, FY23. Later reports restate some prior-year write-off figures slightly; each year's own report is used.

Sheet Capital
A1: Capital adequacy, net worth and leverage (consolidated; CRAR standalone)
A2: CRAR / Tier 1 are regulatory ratios reported only for the standalone company (same as in the Bajaj file). Borrowings = debt securities + other borrowings + deposits + subordinated liabilities.
A4: Financial year | B4: CRAR % (standalone) | C4: Tier 1 % (standalone) | D4: Tier 2 % (calc) | E4: Debt securities | F4: Borrowings (other than debt sec.) | G4: Deposits | H4: Total assets | I4: Equity — owners | J4: Non-controlling interests | K4: Subordinated liabilities | L4: Total borrowings | M4: Total equity (calc) | N4: Debt / Equity (x, calc) | O4: Leverage: assets / equity (x, calc) | P4: Source (document · slide/page)
A5: FY2016-17 | B5: 0.172 | C5: 0.128 | D5: =IF(OR(B5=""),"",B5-C5) -> 0.044 | G5: 4263.57 | H5: 53406.57 | I5: 6960.16 | J5: 99.8 | K5: 2319.1 | L5: 40811.05 | M5: =IF(OR(I5="",J5=""),"",I5+J5) -> 7059.96 | N5: =IF(OR(L5="",M5=""),"",L5/M5) -> 5.7806347 | O5: =IF(OR(H5="",M5=""),"",H5/M5) -> 7.5647128 | P5: AR 2016-17 BS p.204; borrowings pp.218-220; CRAR p.100 (standalone)
A6: FY2017-18 | B6: 0.22 | C6: 0.161 | D6: =IF(OR(B6=""),"",B6-C6) -> 0.059 | E6: 21944.36 | F6: 16527.24 | G6: 3052.05 | H6: 58730.14 | I6: 9855 | J6: 145.1 | K6: 3462.5 | L6: =IF(COUNT(E6,F6,G6,K6)<4,"",E6+F6+G6+K6) -> 44986.15 | M6: =IF(OR(I6="",J6=""),"",I6+J6) -> 10000.1 | N6: =IF(OR(L6="",M6=""),"",L6/M6) -> 4.49857 | O6: =IF(OR(H6="",M6=""),"",H6/M6) -> 5.8729553 | P6: AR 2018-19 (FY18 Ind AS comparatives) BS p.250; CRAR/Tier 1 standalone (see standalone file)
A7: FY2018-19 | B7: 0.203 | C7: 0.155 | D7: =IF(OR(B7=""),"",B7-C7) -> 0.048 | E7: 24715.89 | F7: 24632.72 | G7: 5630.93 | H7: 74575.97 | I7: 11269.02 | J7: 78.51 | K7: 3822.08 | L7: =IF(COUNT(E7,F7,G7,K7)<4,"",E7+F7+G7+K7) -> 58801.62 | M7: =IF(OR(I7="",J7=""),"",I7+J7) -> 11347.53 | N7: =IF(OR(L7="",M7=""),"",L7/M7) -> 5.1818872 | O7: =IF(OR(H7="",M7=""),"",H7/M7) -> 6.5720003 | P7: AR 2018-19 BS p.250; CRAR/Tier 1 standalone (see standalone file)
A8: FY2019-20 | B8: 0.196 | C8: 0.154 | D8: =IF(OR(B8=""),"",B8-C8) -> 0.042 | E8: 19744.61 | F8: 33327.14 | G8: 8781.39 | H8: 81792.58 | I8: 11969 | J8: 89.68 | K8: 3781.1 | L8: =IF(COUNT(E8,F8,G8,K8)<4,"",E8+F8+G8+K8) -> 65634.24 | M8: =IF(OR(I8="",J8=""),"",I8+J8) -> 12058.68 | N8: =IF(OR(L8="",M8=""),"",L8/M8) -> 5.4429042 | O8: =IF(OR(H8="",M8=""),"",H8/M8) -> 6.78288 | P8: AR 2019-20 BS p.276; CRAR/Tier 1 standalone (see standalone file)
A9: FY2020-21 | B9: 0.26 | C9: 0.222 | D9: =IF(OR(B9=""),"",B9-C9) -> 0.038 | E9: 19671.04 | F9: 32454.28 | G9: 9366.16 | H9: 85600.99 | I9: 15776.37 | J9: 99.15 | K9: 3609.47 | L9: =IF(COUNT(E9,F9,G9,K9)<4,"",E9+F9+G9+K9) -> 65100.95 | M9: =IF(OR(I9="",J9=""),"",I9+J9) -> 15875.52 | N9: =IF(OR(L9="",M9=""),"",L9/M9) -> 4.1007129 | O9: =IF(OR(H9="",M9=""),"",H9/M9) -> 5.3920117 | P9: IAR 2020-21 BS p.330; CRAR/Tier 1 standalone (see standalone file)
A10: FY2021-22 | B10: 0.278 | C10: 0.243 | D10: =IF(OR(B10=""),"",B10-C10) -> 0.035 | E10: 21597.15 | F10: 28652.09 | G10: 8286.26 | H10: 83808.65 | I10: 16896.31 | J10: 141.46 | K10: 3590.13 | L10: =IF(COUNT(E10,F10,G10,K10)<4,"",E10+F10+G10+K10) -> 62125.63 | M10: =IF(OR(I10="",J10=""),"",I10+J10) -> 17037.77 | N10: =IF(OR(L10="",M10=""),"",L10/M10) -> 3.6463475 | O10: =IF(OR(H10="",M10=""),"",H10/M10) -> 4.9189917 | P10: IR 2021-22 BS p.326; CRAR/Tier 1 standalone (see standalone file)
A11: FY2022-23 | B11: 0.225 | C11: 0.199 | D11: =IF(OR(B11=""),"",B11-C11) -> 0.026 | E11: 27912.79 | F11: 44154.4 | G11: 5458.74 | H11: 105084.77 | I11: 18560.09 | J11: 141.35 | K11: 3902.63 | L11: =IF(COUNT(E11,F11,G11,K11)<4,"",E11+F11+G11+K11) -> 81428.56 | M11: =IF(OR(I11="",J11=""),"",I11+J11) -> 18701.44 | N11: =IF(OR(L11="",M11=""),"",L11/M11) -> 4.3541332 | O11: =IF(OR(H11="",M11=""),"",H11/M11) -> 5.6190737 | P11: IR 2022-23 BS p.412; CRAR/Tier 1 standalone (see standalone file)
A12: FY2023-24 | B12: 0.189 | C12: 0.164 | D12: =IF(OR(B12=""),"",B12-C12) -> 0.025 | E12: 29888.41 | F12: 56789.54 | G12: 7174.73 | H12: 123715.79 | I12: 19933.25 | J12: 41.61 | K12: 4466.45 | L12: =IF(COUNT(E12,F12,G12,K12)<4,"",E12+F12+G12+K12) -> 98319.13 | M12: =IF(OR(I12="",J12=""),"",I12+J12) -> 19974.86 | N12: =IF(OR(L12="",M12=""),"",L12/M12) -> 4.9221436 | O12: =IF(OR(H12="",M12=""),"",H12/M12) -> 6.1935748 | P12: IR 2023-24 BS p.396; CRAR/Tier 1 standalone (see standalone file)
A13: FY2024-25 | B13: 0.183 | C13: 0.152 | D13: =IF(OR(B13=""),"",B13-C13) -> 0.031 | M13: =IF(OR(I13="",J13=""),"",I13+J13) | N13: =IF(OR(L13="",M13=""),"",L13/M13) | O13: =IF(OR(H13="",M13=""),"",H13/M13) | P13: Pending – AR 2024-25
A14: FY2025-26 | B14: 0.188 | C14: 0.167 | D14: =IF(OR(B14=""),"",B14-C14) -> 0.021 | M14: =IF(OR(I14="",J14=""),"",I14+J14) | N14: =IF(OR(L14="",M14=""),"",L14/M14) | O14: =IF(OR(H14="",M14=""),"",H14/M14) | P14: Pending – IAR 2025-26
A16: CRAR / Tier 1: FY17 from AR 2016-17 p.100; FY18–FY26 from the standalone file (Mahindra investor presentations) — they are standalone in every year, including FY25–FY26.
A17: FY17 (IGAAP) total borrowings ₹40,811 cr = long-term ₹24,985 cr + short-term ₹7,218 cr + current maturities ₹8,609 cr; deposits (₹4,264 cr) and sub-debt (₹2,319 cr) are inside that total, and the debt-securities / bank split was not extracted (yellow).
A18: FY17 equity = shareholders' funds; NCI = minority interest. FY18 IGAAP: total assets ₹63,538 cr, net worth ₹9,915 cr (AR 2017-18 p.218).

Sheet Profitability
A1: Profitability (₹ crore, consolidated)
A2: NTI = total income − finance costs. Opex = employee + depreciation + other expenses + fees & commission expense. PPOP = NTI − opex. ROA / ROE calculated on averages.
A4: Financial year | B4: Total income | C4: Interest income | D4: Finance costs | E4: Employee benefits | F4: Depreciation & amortisation | G4: Other expenses | H4: Fees & commission expense | I4: NTI (calc) | J4: Opex (calc) | K4: PPOP (calc) | L4: Profit before tax | M4: Profit for the year | N4: PAT — owners of the company | O4: ROA % (calc) | P4: ROE % (calc) | Q4: Cost-to-income (Opex / NTI) | R4: Loan losses / NTI | S4: PAT growth % | T4: Source (document · slide/page)
A5: FY2016-17 | B5: 7200.65 | D5: 3186.17 | E5: 886.64 | F5: 53.72 | G5: 846.81 | H5: 0 | I5: =IF(OR(B5="",D5=""),"",B5-D5) -> 4014.48 | J5: =IF(COUNT(E5:H5)<4,"",SUM(E5:H5)) -> 1787.17 | K5: =IF(OR(I5="",J5=""),"",I5-J5) -> 2227.31 | L5: 837.75 | M5: 529.7 | N5: 511.64 | Q5: =IF(OR(J5="",I5=""),"",J5/I5) -> 0.44518094 | R5: =IF(OR(Credit_Losses!B5="",I5=""),"",Credit_Losses!B5/I5) -> 0.34613449 | T5: AR 2016-17 p.205 (IGAAP); PAT before minority from AR 2017-18 p.219
A6: FY2017-18 | B6: 7912.18 | C6: 7605.41 | D6: 3436.19 | E6: 1136.61 | F6: 55.21 | G6: 665.27 | H6: 67.92 | I6: =IF(OR(B6="",D6=""),"",B6-D6) -> 4475.99 | J6: =IF(COUNT(E6:H6)<4,"",SUM(E6:H6)) -> 1925.01 | K6: =IF(OR(I6="",J6=""),"",I6-J6) -> 2550.98 | L6: 1904.8 | M6: 1216.29 | N6: 1185.19 | O6: =IF(OR(M6="",Capital!$H6="",Capital!$H5=""),"",M6/AVERAGE(Capital!$H6,Capital!$H5)) -> 0.021692985 | P6: =IF(OR(N6="",Capital!$I6="",Capital!$I5=""),"",N6/AVERAGE(Capital!$I6,Capital!$I5)) -> 0.14096684 | Q6: =IF(OR(J6="",I6=""),"",J6/I6) -> 0.43007469 | R6: =IF(OR(Credit_Losses!B6="",I6=""),"",Credit_Losses!B6/I6) -> 0.15122018 | S6: =IF(OR(N6="",N5=""),"",N6/N5-1) -> 1.316453 | T6: AR 2018-19 (FY18 Ind AS comparatives) p.251
A7: FY2018-19 | B7: 10430.85 | C7: 9969.53 | D7: 4432.28 | E7: 1477.95 | F7: 75.53 | G7: 804.47 | H7: 129.68 | I7: =IF(OR(B7="",D7=""),"",B7-D7) -> 5998.57 | J7: =IF(COUNT(E7:H7)<4,"",SUM(E7:H7)) -> 2487.63 | K7: =IF(OR(I7="",J7=""),"",I7-J7) -> 3510.94 | L7: 2840.76 | M7: 1867.28 | N7: 1827.3 | O7: =IF(OR(M7="",Capital!$H7="",Capital!$H6=""),"",M7/AVERAGE(Capital!$H7,Capital!$H6)) -> 0.02801492 | P7: =IF(OR(N7="",Capital!$I7="",Capital!$I6=""),"",N7/AVERAGE(Capital!$I7,Capital!$I6)) -> 0.17300684 | Q7: =IF(OR(J7="",I7=""),"",J7/I7) -> 0.41470384 | R7: =IF(OR(Credit_Losses!B7="",I7=""),"",Credit_Losses!B7/I7) -> 0.11954683 | S7: =IF(OR(N7="",N6=""),"",N7/N6-1) -> 0.54177811 | T7: AR 2018-19 p.251
A8: FY2019-20 | B8: 11996.46 | C8: 11457.61 | D8: 5390.56 | E8: 1609.82 | F8: 146.87 | G8: 849.2 | H8: 124.9 | I8: =IF(OR(B8="",D8=""),"",B8-D8) -> 6605.9 | J8: =IF(COUNT(E8:H8)<4,"",SUM(E8:H8)) -> 2730.79 | K8: =IF(OR(I8="",J8=""),"",I8-J8) -> 3875.11 | L8: 1602.03 | M8: 1085.82 | N8: 1075.15 | O8: =IF(OR(M8="",Capital!$H8="",Capital!$H7=""),"",M8/AVERAGE(Capital!$H8,Capital!$H7)) -> 0.013887959 | P8: =IF(OR(N8="",Capital!$I8="",Capital!$I7=""),"",N8/AVERAGE(Capital!$I8,Capital!$I7)) -> 0.092533701 | Q8: =IF(OR(J8="",I8=""),"",J8/I8) -> 0.41338652 | R8: =IF(OR(Credit_Losses!B8="",I8=""),"",Credit_Losses!B8/I8) -> 0.35104679 | S8: =IF(OR(N8="",N7=""),"",N8/N7-1) -> -0.41161823 | T8: AR 2019-20 p.277
A9: FY2020-21 | B9: 12170.5 | C9: 11703.79 | D9: 5307.57 | E9: 1384.01 | F9: 150.51 | G9: 558.81 | H9: 104.8 | I9: =IF(OR(B9="",D9=""),"",B9-D9) -> 6862.93 | J9: =IF(COUNT(E9:H9)<4,"",SUM(E9:H9)) -> 2198.13 | K9: =IF(OR(I9="",J9=""),"",I9-J9) -> 4664.8 | L9: 934.14 | M9: 780.28 | N9: 773.21 | O9: =IF(OR(M9="",Capital!$H9="",Capital!$H8=""),"",M9/AVERAGE(Capital!$H9,Capital!$H8)) -> 0.0093226998 | P9: =IF(OR(N9="",Capital!$I9="",Capital!$I8=""),"",N9/AVERAGE(Capital!$I9,Capital!$I8)) -> 0.055736146 | Q9: =IF(OR(J9="",I9=""),"",J9/I9) -> 0.32029031 | R9: =IF(OR(Credit_Losses!B9="",I9=""),"",Credit_Losses!B9/I9) -> 0.58265784 | S9: =IF(OR(N9="",N8=""),"",N9/N8-1) -> -0.28083523 | T9: IAR 2020-21 p.331
A10: FY2021-22 | B10: 11400.51 | C10: 10858.08 | D10: 4417.37 | E10: 1613.12 | F10: 151.99 | G10: 887.71 | H10: 156.11 | I10: =IF(OR(B10="",D10=""),"",B10-D10) -> 6983.14 | J10: =IF(COUNT(E10:H10)<4,"",SUM(E10:H10)) -> 2808.93 | K10: =IF(OR(I10="",J10=""),"",I10-J10) -> 4174.21 | L10: 1549.42 | M10: 1150.34 | N10: 1136.87 | O10: =IF(OR(M10="",Capital!$H10="",Capital!$H9=""),"",M10/AVERAGE(Capital!$H10,Capital!$H9)) -> 0.013580573 | P10: =IF(OR(N10="",Capital!$I10="",Capital!$I9=""),"",N10/AVERAGE(Capital!$I10,Capital!$I9)) -> 0.069591475 | Q10: =IF(OR(J10="",I10=""),"",J10/I10) -> 0.40224455 | R10: =IF(OR(Credit_Losses!B10="",I10=""),"",Credit_Losses!B10/I10) -> 0.38526795 | S10: =IF(OR(N10="",N9=""),"",N10/N9-1) -> 0.47032501 | T10: IR 2021-22 p.327
A11: FY2022-23 | B11: 12832.4 | C11: 12029.51 | D11: 5094.3 | E11: 2115.33 | F11: 225.96 | G11: 1112.46 | H11: 285.26 | I11: =IF(OR(B11="",D11=""),"",B11-D11) -> 7738.1 | J11: =IF(COUNT(E11:H11)<4,"",SUM(E11:H11)) -> 3739.01 | K11: =IF(OR(I11="",J11=""),"",I11-J11) -> 3999.09 | L11: 2803.76 | M11: 2071.2 | N11: 2072.4 | O11: =IF(OR(M11="",Capital!$H11="",Capital!$H10=""),"",M11/AVERAGE(Capital!$H11,Capital!$H10)) -> 0.021929827 | P11: =IF(OR(N11="",Capital!$I11="",Capital!$I10=""),"",N11/AVERAGE(Capital!$I11,Capital!$I10)) -> 0.1168985 | Q11: =IF(OR(J11="",I11=""),"",J11/I11) -> 0.48319484 | R11: =IF(OR(Credit_Losses!B11="",I11=""),"",Credit_Losses!B11/I11) -> 0.15282692 | S11: =IF(OR(N11="",N10=""),"",N11/N10-1) -> 0.82289972 | T11: IR 2022-23 p.413
A12: FY2023-24 | B12: 15970.32 | C12: 14412.33 | D12: 6959.2 | E12: 2261.44 | F12: 274.85 | G12: 1119.17 | H12: 867.84 | I12: =IF(OR(B12="",D12=""),"",B12-D12) -> 9011.12 | J12: =IF(COUNT(E12:H12)<4,"",SUM(E12:H12)) -> 4523.3 | K12: =IF(OR(I12="",J12=""),"",I12-J12) -> 4487.82 | L12: 2588.18 | M12: 1943.05 | N12: 1932.69 | O12: =IF(OR(M12="",Capital!$H12="",Capital!$H11=""),"",M12/AVERAGE(Capital!$H12,Capital!$H11)) -> 0.016984661 | P12: =IF(OR(N12="",Capital!$I12="",Capital!$I11=""),"",N12/AVERAGE(Capital!$I12,Capital!$I11)) -> 0.10041685 | Q12: =IF(OR(J12="",I12=""),"",J12/I12) -> 0.50196868 | R12: =IF(OR(Credit_Losses!B12="",I12=""),"",Credit_Losses!B12/I12) -> 0.21703739 | S12: =IF(OR(N12="",N11=""),"",N12/N11-1) -> -0.067414592 | T12: IR 2023-24 p.397
A13: FY2024-25 | I13: =IF(OR(B13="",D13=""),"",B13-D13) | J13: =IF(COUNT(E13:H13)<4,"",SUM(E13:H13)) | K13: =IF(OR(I13="",J13=""),"",I13-J13) | O13: =IF(OR(M13="",Capital!$H13="",Capital!$H12=""),"",M13/AVERAGE(Capital!$H13,Capital!$H12)) | P13: =IF(OR(N13="",Capital!$I13="",Capital!$I12=""),"",N13/AVERAGE(Capital!$I13,Capital!$I12)) | Q13: =IF(OR(J13="",I13=""),"",J13/I13) | R13: =IF(OR(Credit_Losses!B13="",I13=""),"",Credit_Losses!B13/I13) | S13: =IF(OR(N13="",N12=""),"",N13/N12-1) | T13: Pending – AR 2024-25
A14: FY2025-26 | I14: =IF(OR(B14="",D14=""),"",B14-D14) | J14: =IF(COUNT(E14:H14)<4,"",SUM(E14:H14)) | K14: =IF(OR(I14="",J14=""),"",I14-J14) | O14: =IF(OR(M14="",Capital!$H14="",Capital!$H13=""),"",M14/AVERAGE(Capital!$H14,Capital!$H13)) | P14: =IF(OR(N14="",Capital!$I14="",Capital!$I13=""),"",N14/AVERAGE(Capital!$I14,Capital!$I13)) | Q14: =IF(OR(J14="",I14=""),"",J14/I14) | R14: =IF(OR(Credit_Losses!B14="",I14=""),"",Credit_Losses!B14/I14) | S14: =IF(OR(N14="",N13=""),"",N14/N13-1) | T14: Pending – IAR 2025-26
A16: FY17 IGAAP: commission & brokerage is inside other expenses (no separate fees line, so 0); interest income not separately extracted (yellow). FY18 IGAAP PAT was ₹1,024 cr; Ind AS ₹1,185 cr (owners) used.
A17: PPOP (calc) includes nothing from associates; PBT also includes share of profit of associates/JV (FY18 ₹31 cr … FY24 ₹56 cr) and exceptional items (FY21 +₹229 cr, FY22 +₹21 cr, FY23 −₹56 cr).
A18: ROA = profit for the year ÷ average total assets; ROE = PAT (owners) ÷ average owners' equity (both from Capital sheet).

Sheet Liquidity
A1: Liquidity and funding mix (₹ crore, consolidated balance sheet)
A2: Liquid assets = cash & cash equivalents + other bank balances. Funding mix = share of total borrowings. Liquidity buffer, LCR and ALM buckets are disclosed only standalone — see the standalone file.
